Workbook

Sheet Charts
A1: Charts
A2: Native Excel charts linked to the tables — change an input and they update. Q1 = lowest-income fifth of areas (by earners), Q5 = highest.
A4: 1. Raw numbers — how many BEVs
A69: 2. Income — BEV share and fleet rates
A134: 3. The 2026 fuel crisis
A178: 4. Top areas (full tables on the Top10 sheet)

Sheet Summary
A1: EV take-up by regional income — NSW, QLD, VIC
A2: Public state registration data vs ATO/ABS income by area. All numbers below are live formulas.
A4: Measure | B4: NSW | C4: QLD | D4: VIC | E4: Note
A5: NEW REGISTRATIONS (recent window)
A6: Window | B6: =TEXT(Inputs!$B$18,"mmm yyyy")&" – "&TEXT(Inputs!$B$16,"mmm yyyy") -> Sep 2025 – Aug 2026 | C6: =TEXT(Inputs!$B$19,"mmm yyyy")&" – "&TEXT(Inputs!$B$17,"mmm yyyy") -> Sep 2025 – Aug 2026 | D6: ="Snapshot "&TEXT(Inputs!$B$24,"mmm yyyy") -> Snapshot Jun 2026 | E6: VIC: no monthly regional series; recent-model vehicles in the fleet stand in
A7: New private registrations (count) | B7: =Flow_Group_Summary!F10 -> 282260.66 | C7: =Flow_Group_Summary!F18 -> 130616 | D7: =Flow_Group_Summary!F29 -> 422596 | E7: VIC: recent-model vehicles in the fleet
A8: New BEVs (count) | B8: =Raw_Numbers!K10 -> 46673.2 | C8: =Raw_Numbers!L10 -> 27841 | D8: =Raw_Numbers!M10 -> 60724
A9: New BEVs — lowest-income group Q1 (count) | B9: =Raw_Numbers!K5 -> 6179.25 | C9: =Raw_Numbers!L5 -> 3850 | D9: =Raw_Numbers!M5 -> 10556
A10: New BEVs — highest-income group Q5 (count) | B10: =Raw_Numbers!K9 -> 13189.275 | C10: =Raw_Numbers!L9 -> 10908 | D10: =Raw_Numbers!M9 -> 14861
A11: BEV share — all areas | B11: =Flow_Group_Summary!H10 -> 0.16535496 | C11: =Flow_Group_Summary!H18 -> 0.21315153 | D11: =Flow_Group_Summary!H29 -> 0.14369279
A12: BEV share — Q1 | B12: =Flow_Group_Summary!H5 -> 0.11327734 | C12: =Flow_Group_Summary!H13 -> 0.15853407 | D12: =Flow_Group_Summary!H24 -> 0.12258739
A13: BEV share — Q5 | B13: =Flow_Group_Summary!H9 -> 0.25071361 | C13: =Flow_Group_Summary!H17 -> 0.28606646 | D13: =Flow_Group_Summary!H28 -> 0.17597812
A14: BEV share Q5 ÷ Q1 | B14: =Flow_Group_Summary!H11 -> 2.2132724 | C14: =Flow_Group_Summary!H19 -> 1.8044478 | D14: =Flow_Group_Summary!H30 -> 1.435532 | E14: Times more likely a new car is a BEV in the richest vs poorest fifth of areas
A15: BEV share Q5 ÷ Q1 — first 12 months of data (2023) | B15: =Flow_Group_Summary!O11 -> 2.8239379 | C15: =Flow_Group_Summary!O19 -> 2.2465957 | E15: Lower now than in 2023 = the gap is narrowing as BEVs go mainstream
A16: REGISTERED FLEET (latest snapshot)
A17: Snapshot | B17: =TEXT(Inputs!$B$22,"mmm yyyy") -> Aug 2026 | C17: =TEXT(Inputs!$B$23,"mmm yyyy") -> Aug 2026 | D17: =TEXT(Inputs!$B$24,"mmm yyyy") -> Jun 2026
A18: BEVs in the fleet (count) | B18: =Raw_Numbers!N10 -> 161512.24 | C18: =Raw_Numbers!O10 -> 100829 | D18: =Raw_Numbers!P10 -> 135025 | E18: QLD: BEVs seen in any registration record since Jan 2022 (no public fleet data by region)
A19: BEVs in the fleet — Q1 (count) | B19: =Raw_Numbers!N5 -> 20720.64 | C19: =Raw_Numbers!O5 -> 11967 | D19: =Raw_Numbers!P5 -> 23022
A20: BEVs in the fleet — Q5 (count) | B20: =Raw_Numbers!N9 -> 47038 | C20: =Raw_Numbers!O9 -> 45082 | D20: =Raw_Numbers!P9 -> 35965
A21: BEVs per 1,000 vehicles — all areas | B21: =Stock_Group!Q21 -> 28.03504 | C21: n/a | D21: =Stock_Group!AA59 -> 23.594298
A22: BEVs per 1,000 vehicles — Q1 | B22: =Stock_Group!L21 -> 14.83503 | C22: n/a | D22: =Stock_Group!V59 -> 16.815267
A23: BEVs per 1,000 vehicles — Q5 | B23: =Stock_Group!P21 -> 52.839394 | C23: n/a | D23: =Stock_Group!Z59 -> 38.997483
A24: 2026 FUEL CRISIS (Middle East / Strait of Hormuz)
A25: Crisis window (onset detected from pump prices) | B25: =TEXT(Inputs!$B$28,"mmm yyyy")&" – "&TEXT(Inputs!$B$29,"mmm yyyy") -> Mar 2026 – Aug 2026 | C25: =TEXT(Inputs!$B$28,"mmm yyyy")&" – "&TEXT(Inputs!$B$29,"mmm yyyy") -> Mar 2026 – Aug 2026 | D25: ="Quarter to "&TEXT(Inputs!$B$24,"mmm yyyy") -> Quarter to Jun 2026 | E25: Compared with the same months a year earlier
A26: Retail ULP: pre-crisis average → crisis peak (c/L) | B26: =TEXT(AVERAGEIFS(Fuel_Crisis!B5:B48,Fuel_Crisis!A5:A48,">="&Inputs!$B$33,Fuel_Crisis!A5:A48,"<="&Inputs!$B$34),"0")&" → "&TEXT(_xlfn.MAXIFS(Fuel_Crisis!B5:B48,Fuel_Crisis!G5:G48,1),"0") -> 177 → 229 | C26: =TEXT(AVERAGEIFS(Fuel_Crisis!D5:D48,Fuel_Crisis!A5:A48,">="&Inputs!$B$33,Fuel_Crisis!A5:A48,"<="&Inputs!$B$34),"0")&" → "&TEXT(_xlfn.MAXIFS(Fuel_Crisis!D5:D48,Fuel_Crisis!G5:G48,1),"0") -> 180 → 229
A27: New BEVs, same months a year earlier (count) | B27: =Fuel_Crisis!G58 -> 13472 | C27: =Fuel_Crisis!G66 -> 7455 | D27: =Fuel_Crisis!H77 -> 8853 | E27: VIC: BEVs added to the fleet in the same quarter a year earlier
A28: New BEVs, crisis months (count) | B28: =Fuel_Crisis!D58 -> 32120.35 | C28: =Fuel_Crisis!D66 -> 20380 | D28: =Fuel_Crisis!E77 -> 21349 | E28: VIC: BEVs added to the fleet in the crisis quarter
A29: New petrol/diesel/hybrid regos, change vs a year earlier | B29: =Fuel_Crisis!N58 -> -0.097665511 | C29: =Fuel_Crisis!N66 -> -0.11712823
A30: BEV share: year earlier → crisis | B30: =TEXT(Fuel_Crisis!H58,"0.0%")&" → "&TEXT(Fuel_Crisis!E58,"0.0%") -> 9.4% → 21.6% | C30: =TEXT(Fuel_Crisis!H66,"0.0%")&" → "&TEXT(Fuel_Crisis!E66,"0.0%") -> 11.3% → 28.3%
A31: BEV share multiple — Q1 (× year earlier) | B31: =Fuel_Crisis!J53 -> 3.0077897 | C31: =Fuel_Crisis!J61 -> 3.2349705 | D31: =Fuel_Crisis!I72 -> 2.5643631 | E31: VIC: multiple of BEVs added to the fleet
A32: BEV share multiple — Q5 (× year earlier) | B32: =Fuel_Crisis!J57 -> 1.9941164 | C32: =Fuel_Crisis!J65 -> 2.1692501 | D32: =Fuel_Crisis!I76 -> 1.9948231 | E32: Bigger multiple in Q1 than Q5 = the shock narrowed the gap in relative terms
A33: BEV share change — Q1 / Q5 (percentage points) | B33: =TEXT(Fuel_Crisis!I53,"0.0")&" / "&TEXT(Fuel_Crisis!I57,"0.0") -> 10.6 / 15.6 | C33: =TEXT(Fuel_Crisis!I61,"0.0")&" / "&TEXT(Fuel_Crisis!I65,"0.0") -> 15.3 / 19.7 | E33: …but richer areas still added more percentage points
A36: How to read this
A37: • Income groups: areas are ranked by median income and cut into five groups that each hold about a fifth of the state's earners (NSW/QLD: LGAs; VIC: postcodes). Group ranks are within each state.
A38: • This is an area-level (ecological) comparison: it shows where BEVs are registered, not the income of the individual buyer. Areas with many retirees or students (e.g. Sunshine Coast, Melbourne CBD) have low median taxable income but not necessarily low wealth.
A39: • Novated leases (FBT-exempt for EVs since July 2022) are often registered to the employee, so they appear as private registrations and tilt BEV take-up towards areas with salaried, higher-income workers.
A40: • QLD LGAs are large (Brisbane alone is about a quarter of QLD earners), so QLD groups are lumpy; NSW LGAs and VIC postcodes give a finer gradient.
A41: • 2026 fuel crisis: the US-Israel war with Iran from late February 2026 and the effective closure of the Strait of Hormuz sent pump prices up by around 60 c/L in March (diesel higher still in April). BEV share of new private cars jumped in both NSW and QLD from March while petrol/diesel/hybrid registrations fell. See the Fuel_Crisis sheet and section 3 of Charts.
A42: • Full sources, definitions and caveats: Notes sheet. Suppression handling for NSW: Suppression sheet.

Sheet Raw_Numbers
A1: Raw numbers — vehicle counts, not shares
A2: New private registrations per month (NSW, QLD) and BEV counts by income group. NSW counts include the estimate for suppressed '<=5' cells (Inputs).
A4: Month | B4: NSW new private regos | C4: NSW BEV | D4: NSW other fuels | E4: QLD new private regos | F4: QLD BEV | G4: QLD other fuels | J4: Income group | K4: NSW new BEVs (recent window) | L4: QLD new BEVs (recent window) | M4: VIC recent-model BEVs in fleet | N4: NSW BEV fleet (latest) | O4: QLD BEVs seen since 2022 (latest) | P4: VIC BEV fleet (latest) | Q4: NSW new BEVs — year before crisis | R4: NSW new BEVs — crisis months | S4: QLD new BEVs — year before crisis | T4: QLD new BEVs — crisis months
A5: =Flow_Group_Month!A5 -> 44927 | B5: =SUM(Flow_Group_Month!B5:F5) -> 21000.302 | C5: =SUM(Flow_Group_Month!G5:K5) -> 1657.175 | D5: =B5-C5 -> 19343.127 | E5: =SUM(Flow_Group_Month!L5:P5) -> 9340 | F5: =SUM(Flow_Group_Month!Q5:U5) -> 1088 | G5: =E5-F5 -> 8252 | J5: Q1 (lowest) | K5: =Flow_Group_Summary!G5 -> 6179.25 | L5: =Flow_Group_Summary!G13 -> 3850 | M5: =Flow_Group_Summary!G24 -> 10556 | N5: =Stock_Group!G21 -> 20720.64 | O5: =Stock_Group!B43 -> 11967 | P5: =Stock_Group!G59 -> 23022 | Q5: =Fuel_Crisis!G53 -> 1449.675 | R5: =Fuel_Crisis!D53 -> 4567.65 | S5: =Fuel_Crisis!G61 -> 852 | T5: =Fuel_Crisis!D61 -> 2959
A6: =Flow_Group_Month!A6 -> 44958 | B6: =SUM(Flow_Group_Month!B6:F6) -> 17404.801 | C6: =SUM(Flow_Group_Month!G6:K6) -> 1681.875 | D6: =B6-C6 -> 15722.926 | E6: =SUM(Flow_Group_Month!L6:P6) -> 8399 | F6: =SUM(Flow_Group_Month!Q6:U6) -> 772 | G6: =E6-F6 -> 7627 | J6: Q2 | K6: =Flow_Group_Summary!G6 -> 6976.475 | L6: =Flow_Group_Summary!G14 -> 5471 | M6: =Flow_Group_Summary!G25 -> 9896 | N6: =Stock_Group!H21 -> 22211.48 | O6: =Stock_Group!C43 -> 20906 | P6: =Stock_Group!H59 -> 22092 | Q6: =Fuel_Crisis!G54 -> 1867.875 | R6: =Fuel_Crisis!D54 -> 4958.15 | S6: =Fuel_Crisis!G62 -> 1464 | T6: =Fuel_Crisis!D62 -> 3965
A7: =Flow_Group_Month!A7 -> 44986 | B7: =SUM(Flow_Group_Month!B7:F7) -> 2772.241 | C7: =SUM(Flow_Group_Month!G7:K7) -> 309.825 | D7: =B7-C7 -> 2462.416 | E7: =SUM(Flow_Group_Month!L7:P7) -> 10429 | F7: =SUM(Flow_Group_Month!Q7:U7) -> 908 | G7: =E7-F7 -> 9521 | J7: Q3 | K7: =Flow_Group_Summary!G7 -> 9659.375 | L7: =Flow_Group_Summary!G15 -> 5705 | M7: =Flow_Group_Summary!G26 -> 12000 | N7: =Stock_Group!I21 -> 30243.44 | O7: =Stock_Group!D43 -> 16754 | P7: =Stock_Group!I59 -> 25104 | Q7: =Fuel_Crisis!G55 -> 2620.75 | R7: =Fuel_Crisis!D55 -> 6742.825 | S7: =Fuel_Crisis!G63 -> 1439 | T7: =Fuel_Crisis!D63 -> 4221
A8: =Flow_Group_Month!A8 -> 45017 | B8: =SUM(Flow_Group_Month!B8:F8) -> 6474.79 | C8: =SUM(Flow_Group_Month!G8:K8) -> 402.9 | D8: =B8-C8 -> 6071.89 | E8: =SUM(Flow_Group_Month!L8:P8) -> 8894 | F8: =SUM(Flow_Group_Month!Q8:U8) -> 1009 | G8: =E8-F8 -> 7885 | J8: Q4 | K8: =Flow_Group_Summary!G8 -> 10668.825 | L8: =Flow_Group_Summary!G16 -> 1907 | M8: =Flow_Group_Summary!G27 -> 13411 | N8: =Stock_Group!J21 -> 41298.68 | O8: =Stock_Group!E43 -> 6120 | P8: =Stock_Group!J59 -> 28842 | Q8: =Fuel_Crisis!G56 -> 3319.325 | R8: =Fuel_Crisis!D56 -> 7209.8 | S8: =Fuel_Crisis!G64 -> 473 | T8: =Fuel_Crisis!D64 -> 1415
A9: =Flow_Group_Month!A9 -> 45047 | B9: =SUM(Flow_Group_Month!B9:F9) -> 22569.653 | C9: =SUM(Flow_Group_Month!G9:K9) -> 1953.55 | D9: =B9-C9 -> 20616.103 | E9: =SUM(Flow_Group_Month!L9:P9) -> 10157 | F9: =SUM(Flow_Group_Month!Q9:U9) -> 822 | G9: =E9-F9 -> 9335 | J9: Q5 (highest) | K9: =Flow_Group_Summary!G9 -> 13189.275 | L9: =Flow_Group_Summary!G17 -> 10908 | M9: =Flow_Group_Summary!G28 -> 14861 | N9: =Stock_Group!K21 -> 47038 | O9: =Stock_Group!F43 -> 45082 | P9: =Stock_Group!K59 -> 35965 | Q9: =Fuel_Crisis!G57 -> 4214.375 | R9: =Fuel_Crisis!D57 -> 8641.925 | S9: =Fuel_Crisis!G65 -> 3227 | T9: =Fuel_Crisis!D65 -> 7820
A10: =Flow_Group_Month!A10 -> 45078 | B10: =SUM(Flow_Group_Month!B10:F10) -> 25547.589 | C10: =SUM(Flow_Group_Month!G10:K10) -> 1972.075 | D10: =B10-C10 -> 23575.514 | E10: =SUM(Flow_Group_Month!L10:P10) -> 11827 | F10: =SUM(Flow_Group_Month!Q10:U10) -> 1332 | G10: =E10-F10 -> 10495 | J10: All | K10: =SUM(K5:K9) -> 46673.2 | L10: =SUM(L5:L9) -> 27841 | M10: =SUM(M5:M9) -> 60724 | N10: =SUM(N5:N9) -> 161512.24 | O10: =SUM(O5:O9) -> 100829 | P10: =SUM(P5:P9) -> 135025 | Q10: =SUM(Q5:Q9) -> 13472 | R10: =SUM(R5:R9) -> 32120.35 | ... T10: =SUM(T5:T9) -> 20380
A11: =Flow_Group_Month!A11 -> 45108 | B11: =SUM(Flow_Group_Month!B11:F11) -> 23180.739 | C11: =SUM(Flow_Group_Month!G11:K11) -> 1869.625 | D11: =B11-C11 -> 21311.114 | E11: =SUM(Flow_Group_Month!L11:P11) -> 10232 | F11: =SUM(Flow_Group_Month!Q11:U11) -> 797 | G11: =E11-F11 -> 9435
A12: =Flow_Group_Month!A12 -> 45139 | B12: =SUM(Flow_Group_Month!B12:F12) -> 26827.429 | C12: =SUM(Flow_Group_Month!G12:K12) -> 1722.15 | D12: =B12-C12 -> 25105.279 | E12: =SUM(Flow_Group_Month!L12:P12) -> 11568 | F12: =SUM(Flow_Group_Month!Q12:U12) -> 1644 | G12: =E12-F12 -> 9924
A13: =Flow_Group_Month!A13 -> 45170 | B13: =SUM(Flow_Group_Month!B13:F13) -> 27571.68 | C13: =SUM(Flow_Group_Month!G13:K13) -> 2553.95 | D13: =B13-C13 -> 25017.73 | E13: =SUM(Flow_Group_Month!L13:P13) -> 11369 | F13: =SUM(Flow_Group_Month!Q13:U13) -> 1290 | G13: =E13-F13 -> 10079
A14: =Flow_Group_Month!A14 -> 45200 | B14: =SUM(Flow_Group_Month!B14:F14) -> 25419.639 | C14: =SUM(Flow_Group_Month!G14:K14) -> 1674.075 | D14: =B14-C14 -> 23745.564 | E14: =SUM(Flow_Group_Month!L14:P14) -> 10644 | F14: =SUM(Flow_Group_Month!Q14:U14) -> 848 | G14: =E14-F14 -> 9796
A15: =Flow_Group_Month!A15 -> 45231 | B15: =SUM(Flow_Group_Month!B15:F15) -> 25930.395 | C15: =SUM(Flow_Group_Month!G15:K15) -> 2385.9 | D15: =B15-C15 -> 23544.495 | E15: =SUM(Flow_Group_Month!L15:P15) -> 11566 | F15: =SUM(Flow_Group_Month!Q15:U15) -> 1641 | G15: =E15-F15 -> 9925
A16: =Flow_Group_Month!A16 -> 45261 | B16: =SUM(Flow_Group_Month!B16:F16) -> 18785.833 | C16: =SUM(Flow_Group_Month!G16:K16) -> 1554.225 | D16: =B16-C16 -> 17231.608 | E16: =SUM(Flow_Group_Month!L16:P16) -> 9399 | F16: =SUM(Flow_Group_Month!Q16:U16) -> 1020 | G16: =E16-F16 -> 8379
A17: =Flow_Group_Month!A17 -> 45292 | B17: =SUM(Flow_Group_Month!B17:F17) -> 21883.976 | C17: =SUM(Flow_Group_Month!G17:K17) -> 1461.15 | D17: =B17-C17 -> 20422.826 | E17: =SUM(Flow_Group_Month!L17:P17) -> 9834 | F17: =SUM(Flow_Group_Month!Q17:U17) -> 1018 | G17: =E17-F17 -> 8816
A18: =Flow_Group_Month!A18 -> 45323 | B18: =SUM(Flow_Group_Month!B18:F18) -> 2719.796 | C18: =SUM(Flow_Group_Month!G18:K18) -> 237.15 | D18: =B18-C18 -> 2482.646 | E18: =SUM(Flow_Group_Month!L18:P18) -> 10845 | F18: =SUM(Flow_Group_Month!Q18:U18) -> 1329 | G18: =E18-F18 -> 9516
A19: =Flow_Group_Month!A19 -> 45352 | B19: =SUM(Flow_Group_Month!B19:F19) -> 5524.269 | C19: =SUM(Flow_Group_Month!G19:K19) -> 508.725 | D19: =B19-C19 -> 5015.544 | E19: =SUM(Flow_Group_Month!L19:P19) -> 11215 | F19: =SUM(Flow_Group_Month!Q19:U19) -> 1511 | G19: =E19-F19 -> 9704
A20: =Flow_Group_Month!A20 -> 45383 | B20: =SUM(Flow_Group_Month!B20:F20) -> 18226.04 | C20: =SUM(Flow_Group_Month!G20:K20) -> 1215.075 | D20: =B20-C20 -> 17010.965 | E20: =SUM(Flow_Group_Month!L20:P20) -> 10246 | F20: =SUM(Flow_Group_Month!Q20:U20) -> 995 | G20: =E20-F20 -> 9251
A21: =Flow_Group_Month!A21 -> 45413 | B21: =SUM(Flow_Group_Month!B21:F21) -> 16782.838 | C21: =SUM(Flow_Group_Month!G21:K21) -> 1297.95 | D21: =B21-C21 -> 15484.888 | E21: =SUM(Flow_Group_Month!L21:P21) -> 11201 | F21: =SUM(Flow_Group_Month!Q21:U21) -> 1572 | G21: =E21-F21 -> 9629
A22: =Flow_Group_Month!A22 -> 45444 | B22: =SUM(Flow_Group_Month!B22:F22) -> 26347.606 | C22: =SUM(Flow_Group_Month!G22:K22) -> 2226.85 | D22: =B22-C22 -> 24120.756 | E22: =SUM(Flow_Group_Month!L22:P22) -> 11976 | F22: =SUM(Flow_Group_Month!Q22:U22) -> 1425 | G22: =E22-F22 -> 10551
... A48: =Flow_Group_Month!A48 -> 46235 | B48: =SUM(Flow_Group_Month!B48:F48) -> 21977.986 | C48: =SUM(Flow_Group_Month!G48:K48) -> 5688.4 | D48: =B48-C48 -> 16289.586 | E48: =SUM(Flow_Group_Month!L48:P48) -> 11707 | F48: =SUM(Flow_Group_Month!Q48:U48) -> 3830 | G48: =E48-F48 -> 7877

Sheet Top10
A1: Top and bottom 10 areas
A2: Suburb-level EV data is not published by any state: VIC is by postcode (named by its ABS suburbs), NSW and QLD by LGA. Only areas above the size thresholds on Inputs are ranked. Live formulas.
A4: NSW LGAs — highest BEV share of new private cars (recent window) | J4: NSW LGAs — lowest BEV share of new private cars (recent window)
A5: # | B5: LGA | C5: Median income ($) | D5: Income group | E5: New regos | F5: BEV share | J5: # | K5: LGA | L5: Median income ($) | M5: Income group | N5: New regos | O5: BEV share
A6: 1 | B6: =IFERROR(INDEX(LGA_Summary!$C:$C,MATCH(LARGE(Rank_Keys!$B:$B,1),Rank_Keys!$B:$B,0)),"") -> Lane Cove | C6: =IFERROR(INDEX(LGA_Summary!$D:$D,MATCH(LARGE(Rank_Keys!$B:$B,1),Rank_Keys!$B:$B,0)),"") -> 85425 | D6: =IFERROR(INDEX(LGA_Summary!$F:$F,MATCH(LARGE(Rank_Keys!$B:$B,1),Rank_Keys!$B:$B,0)),"") -> 5 | E6: =IFERROR(INDEX(LGA_Summary!$G:$G,MATCH(LARGE(Rank_Keys!$B:$B,1),Rank_Keys!$B:$B,0)),"") -> 1709.928 | F6: =IFERROR(INDEX(LGA_Summary!$J:$J,MATCH(LARGE(Rank_Keys!$B:$B,1),Rank_Keys!$B:$B,0)),"") -> 0.32882963 | J6: 1 | K6: =IFERROR(INDEX(LGA_Summary!$C:$C,MATCH(SMALL(Rank_Keys!$C:$C,1),Rank_Keys!$C:$C,0)),"") -> Broken Hill | L6: =IFERROR(INDEX(LGA_Summary!$D:$D,MATCH(SMALL(Rank_Keys!$C:$C,1),Rank_Keys!$C:$C,0)),"") -> 58284 | M6: =IFERROR(INDEX(LGA_Summary!$F:$F,MATCH(SMALL(Rank_Keys!$C:$C,1),Rank_Keys!$C:$C,0)),"") -> 3 | N6: =IFERROR(INDEX(LGA_Summary!$G:$G,MATCH(SMALL(Rank_Keys!$C:$C,1),Rank_Keys!$C:$C,0)),"") -> 439.654 | O6: =IFERROR(INDEX(LGA_Summary!$J:$J,MATCH(SMALL(Rank_Keys!$C:$C,1),Rank_Keys!$C:$C,0)),"") -> 0.014500039
A7: 2 | B7: =IFERROR(INDEX(LGA_Summary!$C:$C,MATCH(LARGE(Rank_Keys!$B:$B,2),Rank_Keys!$B:$B,0)),"") -> Ku-ring-gai | C7: =IFERROR(INDEX(LGA_Summary!$D:$D,MATCH(LARGE(Rank_Keys!$B:$B,2),Rank_Keys!$B:$B,0)),"") -> 69492 | D7: =IFERROR(INDEX(LGA_Summary!$F:$F,MATCH(LARGE(Rank_Keys!$B:$B,2),Rank_Keys!$B:$B,0)),"") -> 5 | E7: =IFERROR(INDEX(LGA_Summary!$G:$G,MATCH(LARGE(Rank_Keys!$B:$B,2),Rank_Keys!$B:$B,0)),"") -> 4912.031 | F7: =IFERROR(INDEX(LGA_Summary!$J:$J,MATCH(LARGE(Rank_Keys!$B:$B,2),Rank_Keys!$B:$B,0)),"") -> 0.31987278 | J7: 2 | K7: =IFERROR(INDEX(LGA_Summary!$C:$C,MATCH(SMALL(Rank_Keys!$C:$C,2),Rank_Keys!$C:$C,0)),"") -> Gwydir | L7: =IFERROR(INDEX(LGA_Summary!$D:$D,MATCH(SMALL(Rank_Keys!$C:$C,2),Rank_Keys!$C:$C,0)),"") -> 43354 | M7: =IFERROR(INDEX(LGA_Summary!$F:$F,MATCH(SMALL(Rank_Keys!$C:$C,2),Rank_Keys!$C:$C,0)),"") -> 1 | N7: =IFERROR(INDEX(LGA_Summary!$G:$G,MATCH(SMALL(Rank_Keys!$C:$C,2),Rank_Keys!$C:$C,0)),"") -> 397.46 | O7: =IFERROR(INDEX(LGA_Summary!$J:$J,MATCH(SMALL(Rank_Keys!$C:$C,2),Rank_Keys!$C:$C,0)),"") -> 0.01603935
A8: 3 | B8: =IFERROR(INDEX(LGA_Summary!$C:$C,MATCH(LARGE(Rank_Keys!$B:$B,3),Rank_Keys!$B:$B,0)),"") -> Willoughby | C8: =IFERROR(INDEX(LGA_Summary!$D:$D,MATCH(LARGE(Rank_Keys!$B:$B,3),Rank_Keys!$B:$B,0)),"") -> 70612 | D8: =IFERROR(INDEX(LGA_Summary!$F:$F,MATCH(LARGE(Rank_Keys!$B:$B,3),Rank_Keys!$B:$B,0)),"") -> 5 | E8: =IFERROR(INDEX(LGA_Summary!$G:$G,MATCH(LARGE(Rank_Keys!$B:$B,3),Rank_Keys!$B:$B,0)),"") -> 3401.751 | F8: =IFERROR(INDEX(LGA_Summary!$J:$J,MATCH(LARGE(Rank_Keys!$B:$B,3),Rank_Keys!$B:$B,0)),"") -> 0.3114646 | J8: 3 | K8: =IFERROR(INDEX(LGA_Summary!$C:$C,MATCH(SMALL(Rank_Keys!$C:$C,3),Rank_Keys!$C:$C,0)),"") -> Moree Plains | L8: =IFERROR(INDEX(LGA_Summary!$D:$D,MATCH(SMALL(Rank_Keys!$C:$C,3),Rank_Keys!$C:$C,0)),"") -> 56977 | M8: =IFERROR(INDEX(LGA_Summary!$F:$F,MATCH(SMALL(Rank_Keys!$C:$C,3),Rank_Keys!$C:$C,0)),"") -> 2 | N8: =IFERROR(INDEX(LGA_Summary!$G:$G,MATCH(SMALL(Rank_Keys!$C:$C,3),Rank_Keys!$C:$C,0)),"") -> 315.486 | O8: =IFERROR(INDEX(LGA_Summary!$J:$J,MATCH(SMALL(Rank_Keys!$C:$C,3),Rank_Keys!$C:$C,0)),"") -> 0.016165535
A9: 4 | B9: =IFERROR(INDEX(LGA_Summary!$C:$C,MATCH(LARGE(Rank_Keys!$B:$B,4),Rank_Keys!$B:$B,0)),"") -> Inner West | C9: =IFERROR(INDEX(LGA_Summary!$D:$D,MATCH(LARGE(Rank_Keys!$B:$B,4),Rank_Keys!$B:$B,0)),"") -> 75949 | D9: =IFERROR(INDEX(LGA_Summary!$F:$F,MATCH(LARGE(Rank_Keys!$B:$B,4),Rank_Keys!$B:$B,0)),"") -> 5 | E9: =IFERROR(INDEX(LGA_Summary!$G:$G,MATCH(LARGE(Rank_Keys!$B:$B,4),Rank_Keys!$B:$B,0)),"") -> 5378.29 | F9: =IFERROR(INDEX(LGA_Summary!$J:$J,MATCH(LARGE(Rank_Keys!$B:$B,4),Rank_Keys!$B:$B,0)),"") -> 0.28874419 | J9: 4 | K9: =IFERROR(INDEX(LGA_Summary!$C:$C,MATCH(SMALL(Rank_Keys!$C:$C,4),Rank_Keys!$C:$C,0)),"") -> Murray River | L9: =IFERROR(INDEX(LGA_Summary!$D:$D,MATCH(SMALL(Rank_Keys!$C:$C,4),Rank_Keys!$C:$C,0)),"") -> 48583 | M9: =IFERROR(INDEX(LGA_Summary!$F:$F,MATCH(SMALL(Rank_Keys!$C:$C,4),Rank_Keys!$C:$C,0)),"") -> 1 | N9: =IFERROR(INDEX(LGA_Summary!$G:$G,MATCH(SMALL(Rank_Keys!$C:$C,4),Rank_Keys!$C:$C,0)),"") -> 484.5 | O9: =IFERROR(INDEX(LGA_Summary!$J:$J,MATCH(SMALL(Rank_Keys!$C:$C,4),Rank_Keys!$C:$C,0)),"") -> 0.018421053
A10: 5 | B10: =IFERROR(INDEX(LGA_Summary!$C:$C,MATCH(LARGE(Rank_Keys!$B:$B,5),Rank_Keys!$B:$B,0)),"") -> North Sydney | C10: =IFERROR(INDEX(LGA_Summary!$D:$D,MATCH(LARGE(Rank_Keys!$B:$B,5),Rank_Keys!$B:$B,0)),"") -> 88760 | D10: =IFERROR(INDEX(LGA_Summary!$F:$F,MATCH(LARGE(Rank_Keys!$B:$B,5),Rank_Keys!$B:$B,0)),"") -> 5 | E10: =IFERROR(INDEX(LGA_Summary!$G:$G,MATCH(LARGE(Rank_Keys!$B:$B,5),Rank_Keys!$B:$B,0)),"") -> 2663.356 | F10: =IFERROR(INDEX(LGA_Summary!$J:$J,MATCH(LARGE(Rank_Keys!$B:$B,5),Rank_Keys!$B:$B,0)),"") -> 0.27669977 | J10: 5 | K10: =IFERROR(INDEX(LGA_Summary!$C:$C,MATCH(SMALL(Rank_Keys!$C:$C,5),Rank_Keys!$C:$C,0)),"") -> Parkes | L10: =IFERROR(INDEX(LGA_Summary!$D:$D,MATCH(SMALL(Rank_Keys!$C:$C,5),Rank_Keys!$C:$C,0)),"") -> 53640 | M10: =IFERROR(INDEX(LGA_Summary!$F:$F,MATCH(SMALL(Rank_Keys!$C:$C,5),Rank_Keys!$C:$C,0)),"") -> 2 | N10: =IFERROR(INDEX(LGA_Summary!$G:$G,MATCH(SMALL(Rank_Keys!$C:$C,5),Rank_Keys!$C:$C,0)),"") -> 483.361 | O10: =IFERROR(INDEX(LGA_Summary!$J:$J,MATCH(SMALL(Rank_Keys!$C:$C,5),Rank_Keys!$C:$C,0)),"") -> 0.01846446
A11: 6 | B11: =IFERROR(INDEX(LGA_Summary!$C:$C,MATCH(LARGE(Rank_Keys!$B:$B,6),Rank_Keys!$B:$B,0)),"") -> Ryde | C11: =IFERROR(INDEX(LGA_Summary!$D:$D,MATCH(LARGE(Rank_Keys!$B:$B,6),Rank_Keys!$B:$B,0)),"") -> 64077 | D11: =IFERROR(INDEX(LGA_Summary!$F:$F,MATCH(LARGE(Rank_Keys!$B:$B,6),Rank_Keys!$B:$B,0)),"") -> 4 | E11: =IFERROR(INDEX(LGA_Summary!$G:$G,MATCH(LARGE(Rank_Keys!$B:$B,6),Rank_Keys!$B:$B,0)),"") -> 4303.523 | F11: =IFERROR(INDEX(LGA_Summary!$J:$J,MATCH(LARGE(Rank_Keys!$B:$B,6),Rank_Keys!$B:$B,0)),"") -> 0.27446118 | J11: 6 | K11: =IFERROR(INDEX(LGA_Summary!$C:$C,MATCH(SMALL(Rank_Keys!$C:$C,6),Rank_Keys!$C:$C,0)),"") -> Narrabri | L11: =IFERROR(INDEX(LGA_Summary!$D:$D,MATCH(SMALL(Rank_Keys!$C:$C,6),Rank_Keys!$C:$C,0)),"") -> 55939 | M11: =IFERROR(INDEX(LGA_Summary!$F:$F,MATCH(SMALL(Rank_Keys!$C:$C,6),Rank_Keys!$C:$C,0)),"") -> 2 | N11: =IFERROR(INDEX(LGA_Summary!$G:$G,MATCH(SMALL(Rank_Keys!$C:$C,6),Rank_Keys!$C:$C,0)),"") -> 402.56 | O11: =IFERROR(INDEX(LGA_Summary!$J:$J,MATCH(SMALL(Rank_Keys!$C:$C,6),Rank_Keys!$C:$C,0)),"") -> 0.019003378
A12: 7 | B12: =IFERROR(INDEX(LGA_Summary!$C:$C,MATCH(LARGE(Rank_Keys!$B:$B,7),Rank_Keys!$B:$B,0)),"") -> Hunters Hill | C12: =IFERROR(INDEX(LGA_Summary!$D:$D,MATCH(LARGE(Rank_Keys!$B:$B,7),Rank_Keys!$B:$B,0)),"") -> 80855 | D12: =IFERROR(INDEX(LGA_Summary!$F:$F,MATCH(LARGE(Rank_Keys!$B:$B,7),Rank_Keys!$B:$B,0)),"") -> 5 | E12: =IFERROR(INDEX(LGA_Summary!$G:$G,MATCH(LARGE(Rank_Keys!$B:$B,7),Rank_Keys!$B:$B,0)),"") -> 893.894 | F12: =IFERROR(INDEX(LGA_Summary!$J:$J,MATCH(LARGE(Rank_Keys!$B:$B,7),Rank_Keys!$B:$B,0)),"") -> 0.27243163 | J12: 7 | K12: =IFERROR(INDEX(LGA_Summary!$C:$C,MATCH(SMALL(Rank_Keys!$C:$C,7),Rank_Keys!$C:$C,0)),"") -> Forbes | L12: =IFERROR(INDEX(LGA_Summary!$D:$D,MATCH(SMALL(Rank_Keys!$C:$C,7),Rank_Keys!$C:$C,0)),"") -> 51698 | M12: =IFERROR(INDEX(LGA_Summary!$F:$F,MATCH(SMALL(Rank_Keys!$C:$C,7),Rank_Keys!$C:$C,0)),"") -> 2 | N12: =IFERROR(INDEX(LGA_Summary!$G:$G,MATCH(SMALL(Rank_Keys!$C:$C,7),Rank_Keys!$C:$C,0)),"") -> 356.575 | O12: =IFERROR(INDEX(LGA_Summary!$J:$J,MATCH(SMALL(Rank_Keys!$C:$C,7),Rank_Keys!$C:$C,0)),"") -> 0.021454112
A13: 8 | B13: =IFERROR(INDEX(LGA_Summary!$C:$C,MATCH(LARGE(Rank_Keys!$B:$B,8),Rank_Keys!$B:$B,0)),"") -> Mosman | C13: =IFERROR(INDEX(LGA_Summary!$D:$D,MATCH(LARGE(Rank_Keys!$B:$B,8),Rank_Keys!$B:$B,0)),"") -> 83702 | D13: =IFERROR(INDEX(LGA_Summary!$F:$F,MATCH(LARGE(Rank_Keys!$B:$B,8),Rank_Keys!$B:$B,0)),"") -> 5 | E13: =IFERROR(INDEX(LGA_Summary!$G:$G,MATCH(LARGE(Rank_Keys!$B:$B,8),Rank_Keys!$B:$B,0)),"") -> 1176.332 | F13: =IFERROR(INDEX(LGA_Summary!$J:$J,MATCH(LARGE(Rank_Keys!$B:$B,8),Rank_Keys!$B:$B,0)),"") -> 0.2622984 | J13: 8 | K13: =IFERROR(INDEX(LGA_Summary!$C:$C,MATCH(SMALL(Rank_Keys!$C:$C,8),Rank_Keys!$C:$C,0)),"") -> Inverell | L13: =IFERROR(INDEX(LGA_Summary!$D:$D,MATCH(SMALL(Rank_Keys!$C:$C,8),Rank_Keys!$C:$C,0)),"") -> 47430 | M13: =IFERROR(INDEX(LGA_Summary!$F:$F,MATCH(SMALL(Rank_Keys!$C:$C,8),Rank_Keys!$C:$C,0)),"") -> 1 | N13: =IFERROR(INDEX(LGA_Summary!$G:$G,MATCH(SMALL(Rank_Keys!$C:$C,8),Rank_Keys!$C:$C,0)),"") -> 454.716 | O13: =IFERROR(INDEX(LGA_Summary!$J:$J,MATCH(SMALL(Rank_Keys!$C:$C,8),Rank_Keys!$C:$C,0)),"") -> 0.022431584
A14: 9 | B14: =IFERROR(INDEX(LGA_Summary!$C:$C,MATCH(LARGE(Rank_Keys!$B:$B,9),Rank_Keys!$B:$B,0)),"") -> Sydney | C14: =IFERROR(INDEX(LGA_Summary!$D:$D,MATCH(LARGE(Rank_Keys!$B:$B,9),Rank_Keys!$B:$B,0)),"") -> 65191 | D14: =IFERROR(INDEX(LGA_Summary!$F:$F,MATCH(LARGE(Rank_Keys!$B:$B,9),Rank_Keys!$B:$B,0)),"") -> 4 | E14: =IFERROR(INDEX(LGA_Summary!$G:$G,MATCH(LARGE(Rank_Keys!$B:$B,9),Rank_Keys!$B:$B,0)),"") -> 4947.778 | F14: =IFERROR(INDEX(LGA_Summary!$J:$J,MATCH(LARGE(Rank_Keys!$B:$B,9),Rank_Keys!$B:$B,0)),"") -> 0.26168312 | J14: 9 | K14: =IFERROR(INDEX(LGA_Summary!$C:$C,MATCH(SMALL(Rank_Keys!$C:$C,9),Rank_Keys!$C:$C,0)),"") -> Weddin | L14: =IFERROR(INDEX(LGA_Summary!$D:$D,MATCH(SMALL(Rank_Keys!$C:$C,9),Rank_Keys!$C:$C,0)),"") -> 41840 | M14: =IFERROR(INDEX(LGA_Summary!$F:$F,MATCH(SMALL(Rank_Keys!$C:$C,9),Rank_Keys!$C:$C,0)),"") -> 1 | N14: =IFERROR(INDEX(LGA_Summary!$G:$G,MATCH(SMALL(Rank_Keys!$C:$C,9),Rank_Keys!$C:$C,0)),"") -> 393.805 | O14: =IFERROR(INDEX(LGA_Summary!$J:$J,MATCH(SMALL(Rank_Keys!$C:$C,9),Rank_Keys!$C:$C,0)),"") -> 0.022663501
A15: 10 | B15: =IFERROR(INDEX(LGA_Summary!$C:$C,MATCH(LARGE(Rank_Keys!$B:$B,10),Rank_Keys!$B:$B,0)),"") -> Waverley | C15: =IFERROR(INDEX(LGA_Summary!$D:$D,MATCH(LARGE(Rank_Keys!$B:$B,10),Rank_Keys!$B:$B,0)),"") -> 75746 | D15: =IFERROR(INDEX(LGA_Summary!$F:$F,MATCH(LARGE(Rank_Keys!$B:$B,10),Rank_Keys!$B:$B,0)),"") -> 5 | E15: =IFERROR(INDEX(LGA_Summary!$G:$G,MATCH(LARGE(Rank_Keys!$B:$B,10),Rank_Keys!$B:$B,0)),"") -> 2650.402 | F15: =IFERROR(INDEX(LGA_Summary!$J:$J,MATCH(LARGE(Rank_Keys!$B:$B,10),Rank_Keys!$B:$B,0)),"") -> 0.26121509 | J15: 10 | K15: =IFERROR(INDEX(LGA_Summary!$C:$C,MATCH(SMALL(Rank_Keys!$C:$C,10),Rank_Keys!$C:$C,0)),"") -> Leeton | L15: =IFERROR(INDEX(LGA_Summary!$D:$D,MATCH(SMALL(Rank_Keys!$C:$C,10),Rank_Keys!$C:$C,0)),"") -> 53020 | M15: =IFERROR(INDEX(LGA_Summary!$F:$F,MATCH(SMALL(Rank_Keys!$C:$C,10),Rank_Keys!$C:$C,0)),"") -> 2 | N15: =IFERROR(INDEX(LGA_Summary!$G:$G,MATCH(SMALL(Rank_Keys!$C:$C,10),Rank_Keys!$C:$C,0)),"") -> 454.818 | O15: =IFERROR(INDEX(LGA_Summary!$J:$J,MATCH(SMALL(Rank_Keys!$C:$C,10),Rank_Keys!$C:$C,0)),"") -> 0.025229872
A18: NSW LGAs — most new BEVs registered (recent window, count) | J18: NSW LGAs — largest BEV fleet (count)
A19: # | B19: LGA | C19: Median income ($) | D19: Income group | E19: New regos | F19: New BEVs | J19: # | K19: LGA | L19: Median income ($) | M19: Income group | N19: Per 1,000 vehicles | O19: BEV fleet
A20: 1 | B20: =IFERROR(INDEX(LGA_Summary!$C:$C,MATCH(LARGE(Rank_Keys!$D:$D,1),Rank_Keys!$D:$D,0)),"") -> Blacktown | C20: =IFERROR(INDEX(LGA_Summary!$D:$D,MATCH(LARGE(Rank_Keys!$D:$D,1),Rank_Keys!$D:$D,0)),"") -> 62478 | D20: =IFERROR(INDEX(LGA_Summary!$F:$F,MATCH(LARGE(Rank_Keys!$D:$D,1),Rank_Keys!$D:$D,0)),"") -> 4 | E20: =IFERROR(INDEX(LGA_Summary!$G:$G,MATCH(LARGE(Rank_Keys!$D:$D,1),Rank_Keys!$D:$D,0)),"") -> 12026.948 | F20: =IFERROR(INDEX(LGA_Summary!$H:$H,MATCH(LARGE(Rank_Keys!$D:$D,1),Rank_Keys!$D:$D,0)),"") -> 2265.6 | J20: 1 | K20: =IFERROR(INDEX(LGA_Summary!$C:$C,MATCH(LARGE(Rank_Keys!$E:$E,1),Rank_Keys!$E:$E,0)),"") -> Sydney | L20: =IFERROR(INDEX(LGA_Summary!$D:$D,MATCH(LARGE(Rank_Keys!$E:$E,1),Rank_Keys!$E:$E,0)),"") -> 65191 | M20: =IFERROR(INDEX(LGA_Summary!$F:$F,MATCH(LARGE(Rank_Keys!$E:$E,1),Rank_Keys!$E:$E,0)),"") -> 4 | N20: =IFERROR(INDEX(LGA_Summary!$Q:$Q,MATCH(LARGE(Rank_Keys!$E:$E,1),Rank_Keys!$E:$E,0)),"") -> 80.333261 | O20: =IFERROR(INDEX(LGA_Summary!$O:$O,MATCH(LARGE(Rank_Keys!$E:$E,1),Rank_Keys!$E:$E,0)),"") -> 9173.52
A21: 2 | B21: =IFERROR(INDEX(LGA_Summary!$C:$C,MATCH(LARGE(Rank_Keys!$D:$D,2),Rank_Keys!$D:$D,0)),"") -> The Hills Shire | C21: =IFERROR(INDEX(LGA_Summary!$D:$D,MATCH(LARGE(Rank_Keys!$D:$D,2),Rank_Keys!$D:$D,0)),"") -> 70634 | D21: =IFERROR(INDEX(LGA_Summary!$F:$F,MATCH(LARGE(Rank_Keys!$D:$D,2),Rank_Keys!$D:$D,0)),"") -> 5 | E21: =IFERROR(INDEX(LGA_Summary!$G:$G,MATCH(LARGE(Rank_Keys!$D:$D,2),Rank_Keys!$D:$D,0)),"") -> 9299.165 | F21: =IFERROR(INDEX(LGA_Summary!$H:$H,MATCH(LARGE(Rank_Keys!$D:$D,2),Rank_Keys!$D:$D,0)),"") -> 2110.8 | J21: 2 | K21: =IFERROR(INDEX(LGA_Summary!$C:$C,MATCH(LARGE(Rank_Keys!$E:$E,2),Rank_Keys!$E:$E,0)),"") -> The Hills Shire | L21: =IFERROR(INDEX(LGA_Summary!$D:$D,MATCH(LARGE(Rank_Keys!$E:$E,2),Rank_Keys!$E:$E,0)),"") -> 70634 | M21: =IFERROR(INDEX(LGA_Summary!$F:$F,MATCH(LARGE(Rank_Keys!$E:$E,2),Rank_Keys!$E:$E,0)),"") -> 5 | N21: =IFERROR(INDEX(LGA_Summary!$Q:$Q,MATCH(LARGE(Rank_Keys!$E:$E,2),Rank_Keys!$E:$E,0)),"") -> 58.472805 | O21: =IFERROR(INDEX(LGA_Summary!$O:$O,MATCH(LARGE(Rank_Keys!$E:$E,2),Rank_Keys!$E:$E,0)),"") -> 8744.88
A22: 3 | B22: =IFERROR(INDEX(LGA_Summary!$C:$C,MATCH(LARGE(Rank_Keys!$D:$D,3),Rank_Keys!$D:$D,0)),"") -> Parramatta | C22: =IFERROR(INDEX(LGA_Summary!$D:$D,MATCH(LARGE(Rank_Keys!$D:$D,3),Rank_Keys!$D:$D,0)),"") -> 61730 | D22: =IFERROR(INDEX(LGA_Summary!$F:$F,MATCH(LARGE(Rank_Keys!$D:$D,3),Rank_Keys!$D:$D,0)),"") -> 3 | E22: =IFERROR(INDEX(LGA_Summary!$G:$G,MATCH(LARGE(Rank_Keys!$D:$D,3),Rank_Keys!$D:$D,0)),"") -> 9961.317 | F22: =IFERROR(INDEX(LGA_Summary!$H:$H,MATCH(LARGE(Rank_Keys!$D:$D,3),Rank_Keys!$D:$D,0)),"") -> 1932.15 | J22: 3 | K22: =IFERROR(INDEX(LGA_Summary!$C:$C,MATCH(LARGE(Rank_Keys!$E:$E,3),Rank_Keys!$E:$E,0)),"") -> Blacktown | L22: =IFERROR(INDEX(LGA_Summary!$D:$D,MATCH(LARGE(Rank_Keys!$E:$E,3),Rank_Keys!$E:$E,0)),"") -> 62478 | M22: =IFERROR(INDEX(LGA_Summary!$F:$F,MATCH(LARGE(Rank_Keys!$E:$E,3),Rank_Keys!$E:$E,0)),"") -> 4 | N22: =IFERROR(INDEX(LGA_Summary!$Q:$Q,MATCH(LARGE(Rank_Keys!$E:$E,3),Rank_Keys!$E:$E,0)),"") -> 31.420735 | O22: =IFERROR(INDEX(LGA_Summary!$O:$O,MATCH(LARGE(Rank_Keys!$E:$E,3),Rank_Keys!$E:$E,0)),"") -> 8076.28
A23: 4 | B23: =IFERROR(INDEX(LGA_Summary!$C:$C,MATCH(LARGE(Rank_Keys!$D:$D,4),Rank_Keys!$D:$D,0)),"") -> Northern Beaches | C23: =IFERROR(INDEX(LGA_Summary!$D:$D,MATCH(LARGE(Rank_Keys!$D:$D,4),Rank_Keys!$D:$D,0)),"") -> 67899 | D23: =IFERROR(INDEX(LGA_Summary!$F:$F,MATCH(LARGE(Rank_Keys!$D:$D,4),Rank_Keys!$D:$D,0)),"") -> 4 | E23: =IFERROR(INDEX(LGA_Summary!$G:$G,MATCH(LARGE(Rank_Keys!$D:$D,4),Rank_Keys!$D:$D,0)),"") -> 8360.411 | F23: =IFERROR(INDEX(LGA_Summary!$H:$H,MATCH(LARGE(Rank_Keys!$D:$D,4),Rank_Keys!$D:$D,0)),"") -> 1855.225 | J23: 4 | K23: =IFERROR(INDEX(LGA_Summary!$C:$C,MATCH(LARGE(Rank_Keys!$E:$E,4),Rank_Keys!$E:$E,0)),"") -> Northern Beaches | L23: =IFERROR(INDEX(LGA_Summary!$D:$D,MATCH(LARGE(Rank_Keys!$E:$E,4),Rank_Keys!$E:$E,0)),"") -> 67899 | M23: =IFERROR(INDEX(LGA_Summary!$F:$F,MATCH(LARGE(Rank_Keys!$E:$E,4),Rank_Keys!$E:$E,0)),"") -> 4 | N23: =IFERROR(INDEX(LGA_Summary!$Q:$Q,MATCH(LARGE(Rank_Keys!$E:$E,4),Rank_Keys!$E:$E,0)),"") -> 42.835221 | O23: =IFERROR(INDEX(LGA_Summary!$O:$O,MATCH(LARGE(Rank_Keys!$E:$E,4),Rank_Keys!$E:$E,0)),"") -> 7438.04
A24: 5 | B24: =IFERROR(INDEX(LGA_Summary!$C:$C,MATCH(LARGE(Rank_Keys!$D:$D,5),Rank_Keys!$D:$D,0)),"") -> Hornsby | C24: =IFERROR(INDEX(LGA_Summary!$D:$D,MATCH(LARGE(Rank_Keys!$D:$D,5),Rank_Keys!$D:$D,0)),"") -> 66555 | D24: =IFERROR(INDEX(LGA_Summary!$F:$F,MATCH(LARGE(Rank_Keys!$D:$D,5),Rank_Keys!$D:$D,0)),"") -> 4 | E24: =IFERROR(INDEX(LGA_Summary!$G:$G,MATCH(LARGE(Rank_Keys!$D:$D,5),Rank_Keys!$D:$D,0)),"") -> 7343.99 | F24: =IFERROR(INDEX(LGA_Summary!$H:$H,MATCH(LARGE(Rank_Keys!$D:$D,5),Rank_Keys!$D:$D,0)),"") -> 1819.925 | J24: 5 | K24: =IFERROR(INDEX(LGA_Summary!$C:$C,MATCH(LARGE(Rank_Keys!$E:$E,5),Rank_Keys!$E:$E,0)),"") -> Parramatta | L24: =IFERROR(INDEX(LGA_Summary!$D:$D,MATCH(LARGE(Rank_Keys!$E:$E,5),Rank_Keys!$E:$E,0)),"") -> 61730 | M24: =IFERROR(INDEX(LGA_Summary!$F:$F,MATCH(LARGE(Rank_Keys!$E:$E,5),Rank_Keys!$E:$E,0)),"") -> 3 | N24: =IFERROR(INDEX(LGA_Summary!$Q:$Q,MATCH(LARGE(Rank_Keys!$E:$E,5),Rank_Keys!$E:$E,0)),"") -> 39.230329 | O24: =IFERROR(INDEX(LGA_Summary!$O:$O,MATCH(LARGE(Rank_Keys!$E:$E,5),Rank_Keys!$E:$E,0)),"") -> 6576.32
A25: 6 | B25: =IFERROR(INDEX(LGA_Summary!$C:$C,MATCH(LARGE(Rank_Keys!$D:$D,6),Rank_Keys!$D:$D,0)),"") -> Central Coast | C25: =IFERROR(INDEX(LGA_Summary!$D:$D,MATCH(LARGE(Rank_Keys!$D:$D,6),Rank_Keys!$D:$D,0)),"") -> 55035 | D25: =IFERROR(INDEX(LGA_Summary!$F:$F,MATCH(LARGE(Rank_Keys!$D:$D,6),Rank_Keys!$D:$D,0)),"") -> 2 | E25: =IFERROR(INDEX(LGA_Summary!$G:$G,MATCH(LARGE(Rank_Keys!$D:$D,6),Rank_Keys!$D:$D,0)),"") -> 10787.014 | F25: =IFERROR(INDEX(LGA_Summary!$H:$H,MATCH(LARGE(Rank_Keys!$D:$D,6),Rank_Keys!$D:$D,0)),"") -> 1623.25 | J25: 6 | K25: =IFERROR(INDEX(LGA_Summary!$C:$C,MATCH(LARGE(Rank_Keys!$E:$E,6),Rank_Keys!$E:$E,0)),"") -> Ku-ring-gai | L25: =IFERROR(INDEX(LGA_Summary!$D:$D,MATCH(LARGE(Rank_Keys!$E:$E,6),Rank_Keys!$E:$E,0)),"") -> 69492 | M25: =IFERROR(INDEX(LGA_Summary!$F:$F,MATCH(LARGE(Rank_Keys!$E:$E,6),Rank_Keys!$E:$E,0)),"") -> 5 | N25: =IFERROR(INDEX(LGA_Summary!$Q:$Q,MATCH(LARGE(Rank_Keys!$E:$E,6),Rank_Keys!$E:$E,0)),"") -> 75.835345 | O25: =IFERROR(INDEX(LGA_Summary!$O:$O,MATCH(LARGE(Rank_Keys!$E:$E,6),Rank_Keys!$E:$E,0)),"") -> 6105.56
A26: 7 | B26: =IFERROR(INDEX(LGA_Summary!$C:$C,MATCH(LARGE(Rank_Keys!$D:$D,7),Rank_Keys!$D:$D,0)),"") -> Ku-ring-gai | C26: =IFERROR(INDEX(LGA_Summary!$D:$D,MATCH(LARGE(Rank_Keys!$D:$D,7),Rank_Keys!$D:$D,0)),"") -> 69492 | D26: =IFERROR(INDEX(LGA_Summary!$F:$F,MATCH(LARGE(Rank_Keys!$D:$D,7),Rank_Keys!$D:$D,0)),"") -> 5 | E26: =IFERROR(INDEX(LGA_Summary!$G:$G,MATCH(LARGE(Rank_Keys!$D:$D,7),Rank_Keys!$D:$D,0)),"") -> 4912.031 | F26: =IFERROR(INDEX(LGA_Summary!$H:$H,MATCH(LARGE(Rank_Keys!$D:$D,7),Rank_Keys!$D:$D,0)),"") -> 1571.225 | J26: 7 | K26: =IFERROR(INDEX(LGA_Summary!$C:$C,MATCH(LARGE(Rank_Keys!$E:$E,7),Rank_Keys!$E:$E,0)),"") -> Central Coast | L26: =IFERROR(INDEX(LGA_Summary!$D:$D,MATCH(LARGE(Rank_Keys!$E:$E,7),Rank_Keys!$E:$E,0)),"") -> 55035 | M26: =IFERROR(INDEX(LGA_Summary!$F:$F,MATCH(LARGE(Rank_Keys!$E:$E,7),Rank_Keys!$E:$E,0)),"") -> 2 | N26: =IFERROR(INDEX(LGA_Summary!$Q:$Q,MATCH(LARGE(Rank_Keys!$E:$E,7),Rank_Keys!$E:$E,0)),"") -> 21.515275 | O26: =IFERROR(INDEX(LGA_Summary!$O:$O,MATCH(LARGE(Rank_Keys!$E:$E,7),Rank_Keys!$E:$E,0)),"") -> 5353.16
A27: 8 | B27: =IFERROR(INDEX(LGA_Summary!$C:$C,MATCH(LARGE(Rank_Keys!$D:$D,8),Rank_Keys!$D:$D,0)),"") -> Inner West | C27: =IFERROR(INDEX(LGA_Summary!$D:$D,MATCH(LARGE(Rank_Keys!$D:$D,8),Rank_Keys!$D:$D,0)),"") -> 75949 | D27: =IFERROR(INDEX(LGA_Summary!$F:$F,MATCH(LARGE(Rank_Keys!$D:$D,8),Rank_Keys!$D:$D,0)),"") -> 5 | E27: =IFERROR(INDEX(LGA_Summary!$G:$G,MATCH(LARGE(Rank_Keys!$D:$D,8),Rank_Keys!$D:$D,0)),"") -> 5378.29 | F27: =IFERROR(INDEX(LGA_Summary!$H:$H,MATCH(LARGE(Rank_Keys!$D:$D,8),Rank_Keys!$D:$D,0)),"") -> 1552.95 | J27: 8 | K27: =IFERROR(INDEX(LGA_Summary!$C:$C,MATCH(LARGE(Rank_Keys!$E:$E,8),Rank_Keys!$E:$E,0)),"") -> Hornsby | L27: =IFERROR(INDEX(LGA_Summary!$D:$D,MATCH(LARGE(Rank_Keys!$E:$E,8),Rank_Keys!$E:$E,0)),"") -> 66555 | M27: =IFERROR(INDEX(LGA_Summary!$F:$F,MATCH(LARGE(Rank_Keys!$E:$E,8),Rank_Keys!$E:$E,0)),"") -> 4 | N27: =IFERROR(INDEX(LGA_Summary!$Q:$Q,MATCH(LARGE(Rank_Keys!$E:$E,8),Rank_Keys!$E:$E,0)),"") -> 49.441925 | O27: =IFERROR(INDEX(LGA_Summary!$O:$O,MATCH(LARGE(Rank_Keys!$E:$E,8),Rank_Keys!$E:$E,0)),"") -> 5151.76
A28: 9 | B28: =IFERROR(INDEX(LGA_Summary!$C:$C,MATCH(LARGE(Rank_Keys!$D:$D,9),Rank_Keys!$D:$D,0)),"") -> Sutherland Shire | C28: =IFERROR(INDEX(LGA_Summary!$D:$D,MATCH(LARGE(Rank_Keys!$D:$D,9),Rank_Keys!$D:$D,0)),"") -> 69239 | D28: =IFERROR(INDEX(LGA_Summary!$F:$F,MATCH(LARGE(Rank_Keys!$D:$D,9),Rank_Keys!$D:$D,0)),"") -> 5 | E28: =IFERROR(INDEX(LGA_Summary!$G:$G,MATCH(LARGE(Rank_Keys!$D:$D,9),Rank_Keys!$D:$D,0)),"") -> 7838.054 | F28: =IFERROR(INDEX(LGA_Summary!$H:$H,MATCH(LARGE(Rank_Keys!$D:$D,9),Rank_Keys!$D:$D,0)),"") -> 1371.475 | J28: 9 | K28: =IFERROR(INDEX(LGA_Summary!$C:$C,MATCH(LARGE(Rank_Keys!$E:$E,9),Rank_Keys!$E:$E,0)),"") -> Sutherland Shire | L28: =IFERROR(INDEX(LGA_Summary!$D:$D,MATCH(LARGE(Rank_Keys!$E:$E,9),Rank_Keys!$E:$E,0)),"") -> 69239 | M28: =IFERROR(INDEX(LGA_Summary!$F:$F,MATCH(LARGE(Rank_Keys!$E:$E,9),Rank_Keys!$E:$E,0)),"") -> 5 | N28: =IFERROR(INDEX(LGA_Summary!$Q:$Q,MATCH(LARGE(Rank_Keys!$E:$E,9),Rank_Keys!$E:$E,0)),"") -> 29.669883 | O28: =IFERROR(INDEX(LGA_Summary!$O:$O,MATCH(LARGE(Rank_Keys!$E:$E,9),Rank_Keys!$E:$E,0)),"") -> 4838.56
A29: 10 | B29: =IFERROR(INDEX(LGA_Summary!$C:$C,MATCH(LARGE(Rank_Keys!$D:$D,10),Rank_Keys!$D:$D,0)),"") -> Wollongong | C29: =IFERROR(INDEX(LGA_Summary!$D:$D,MATCH(LARGE(Rank_Keys!$D:$D,10),Rank_Keys!$D:$D,0)),"") -> 58764 | D29: =IFERROR(INDEX(LGA_Summary!$F:$F,MATCH(LARGE(Rank_Keys!$D:$D,10),Rank_Keys!$D:$D,0)),"") -> 3 | E29: =IFERROR(INDEX(LGA_Summary!$G:$G,MATCH(LARGE(Rank_Keys!$D:$D,10),Rank_Keys!$D:$D,0)),"") -> 6540.812 | F29: =IFERROR(INDEX(LGA_Summary!$H:$H,MATCH(LARGE(Rank_Keys!$D:$D,10),Rank_Keys!$D:$D,0)),"") -> 1311.85 | J29: 10 | K29: =IFERROR(INDEX(LGA_Summary!$C:$C,MATCH(LARGE(Rank_Keys!$E:$E,10),Rank_Keys!$E:$E,0)),"") -> Inner West | L29: =IFERROR(INDEX(LGA_Summary!$D:$D,MATCH(LARGE(Rank_Keys!$E:$E,10),Rank_Keys!$E:$E,0)),"") -> 75949 | M29: =IFERROR(INDEX(LGA_Summary!$F:$F,MATCH(LARGE(Rank_Keys!$E:$E,10),Rank_Keys!$E:$E,0)),"") -> 5 | N29: =IFERROR(INDEX(LGA_Summary!$Q:$Q,MATCH(LARGE(Rank_Keys!$E:$E,10),Rank_Keys!$E:$E,0)),"") -> 48.258851 | O29: =IFERROR(INDEX(LGA_Summary!$O:$O,MATCH(LARGE(Rank_Keys!$E:$E,10),Rank_Keys!$E:$E,0)),"") -> 4707.8
A32: NSW LGAs — biggest rise in BEV share during the fuel crisis | J32: QLD LGAs — highest BEV share of new private cars (recent window)
A33: # | B33: LGA | C33: Median income ($) | D33: Income group | E33: Year earlier | F33: Crisis | G33: Change (pp) | J33: # | K33: LGA | L33: Median income ($) | M33: Income group | N33: New regos | O33: BEV share
A34: 1 | B34: =IFERROR(INDEX(LGA_Summary!$C:$C,MATCH(LARGE(Rank_Keys!$F:$F,1),Rank_Keys!$F:$F,0)),"") -> Bellingen | C34: =IFERROR(INDEX(LGA_Summary!$D:$D,MATCH(LARGE(Rank_Keys!$F:$F,1),Rank_Keys!$F:$F,0)),"") -> 42240 | D34: =IFERROR(INDEX(LGA_Summary!$F:$F,MATCH(LARGE(Rank_Keys!$F:$F,1),Rank_Keys!$F:$F,0)),"") -> 1 | E34: =IFERROR(INDEX(LGA_Summary!$U:$U,MATCH(LARGE(Rank_Keys!$F:$F,1),Rank_Keys!$F:$F,0)),"") -> 0.056598434 | F34: =IFERROR(INDEX(LGA_Summary!$T:$T,MATCH(LARGE(Rank_Keys!$F:$F,1),Rank_Keys!$F:$F,0)),"") -> 0.30421359 | G34: =IFERROR(INDEX(LGA_Summary!$V:$V,MATCH(LARGE(Rank_Keys!$F:$F,1),Rank_Keys!$F:$F,0)),"") -> 24.761515 | J34: 1 | K34: =IFERROR(INDEX(LGA_Summary!$C:$C,MATCH(LARGE(Rank_Keys!$G:$G,1),Rank_Keys!$G:$G,0)),"") -> Brisbane | L34: =IFERROR(INDEX(LGA_Summary!$D:$D,MATCH(LARGE(Rank_Keys!$G:$G,1),Rank_Keys!$G:$G,0)),"") -> 63317 | M34: =IFERROR(INDEX(LGA_Summary!$F:$F,MATCH(LARGE(Rank_Keys!$G:$G,1),Rank_Keys!$G:$G,0)),"") -> 5 | N34: =IFERROR(INDEX(LGA_Summary!$G:$G,MATCH(LARGE(Rank_Keys!$G:$G,1),Rank_Keys!$G:$G,0)),"") -> 34175 | O34: =IFERROR(INDEX(LGA_Summary!$J:$J,MATCH(LARGE(Rank_Keys!$G:$G,1),Rank_Keys!$G:$G,0)),"") -> 0.31098756
A35: 2 | B35: =IFERROR(INDEX(LGA_Summary!$C:$C,MATCH(LARGE(Rank_Keys!$F:$F,2),Rank_Keys!$F:$F,0)),"") -> Kiama | C35: =IFERROR(INDEX(LGA_Summary!$D:$D,MATCH(LARGE(Rank_Keys!$F:$F,2),Rank_Keys!$F:$F,0)),"") -> 53652 | D35: =IFERROR(INDEX(LGA_Summary!$F:$F,MATCH(LARGE(Rank_Keys!$F:$F,2),Rank_Keys!$F:$F,0)),"") -> 2 | E35: =IFERROR(INDEX(LGA_Summary!$U:$U,MATCH(LARGE(Rank_Keys!$F:$F,2),Rank_Keys!$F:$F,0)),"") -> 0.11979236 | F35: =IFERROR(INDEX(LGA_Summary!$T:$T,MATCH(LARGE(Rank_Keys!$F:$F,2),Rank_Keys!$F:$F,0)),"") -> 0.34099013 | G35: =IFERROR(INDEX(LGA_Summary!$V:$V,MATCH(LARGE(Rank_Keys!$F:$F,2),Rank_Keys!$F:$F,0)),"") -> 22.119777 | J35: 2 | K35: =IFERROR(INDEX(LGA_Summary!$C:$C,MATCH(LARGE(Rank_Keys!$G:$G,2),Rank_Keys!$G:$G,0)),"") -> Ipswich | L35: =IFERROR(INDEX(LGA_Summary!$D:$D,MATCH(LARGE(Rank_Keys!$G:$G,2),Rank_Keys!$G:$G,0)),"") -> 59405 | M35: =IFERROR(INDEX(LGA_Summary!$F:$F,MATCH(LARGE(Rank_Keys!$G:$G,2),Rank_Keys!$G:$G,0)),"") -> 3 | N35: =IFERROR(INDEX(LGA_Summary!$G:$G,MATCH(LARGE(Rank_Keys!$G:$G,2),Rank_Keys!$G:$G,0)),"") -> 6467 | O35: =IFERROR(INDEX(LGA_Summary!$J:$J,MATCH(LARGE(Rank_Keys!$G:$G,2),Rank_Keys!$G:$G,0)),"") -> 0.23271996
A36: 3 | B36: =IFERROR(INDEX(LGA_Summary!$C:$C,MATCH(LARGE(Rank_Keys!$F:$F,3),Rank_Keys!$F:$F,0)),"") -> Lane Cove | C36: =IFERROR(INDEX(LGA_Summary!$D:$D,MATCH(LARGE(Rank_Keys!$F:$F,3),Rank_Keys!$F:$F,0)),"") -> 85425 | D36: =IFERROR(INDEX(LGA_Summary!$F:$F,MATCH(LARGE(Rank_Keys!$F:$F,3),Rank_Keys!$F:$F,0)),"") -> 5 | E36: =IFERROR(INDEX(LGA_Summary!$U:$U,MATCH(LARGE(Rank_Keys!$F:$F,3),Rank_Keys!$F:$F,0)),"") -> 0.19798416 | F36: =IFERROR(INDEX(LGA_Summary!$T:$T,MATCH(LARGE(Rank_Keys!$F:$F,3),Rank_Keys!$F:$F,0)),"") -> 0.41608086 | G36: =IFERROR(INDEX(LGA_Summary!$V:$V,MATCH(LARGE(Rank_Keys!$F:$F,3),Rank_Keys!$F:$F,0)),"") -> 21.80967 | J36: 3 | K36: =IFERROR(INDEX(LGA_Summary!$C:$C,MATCH(LARGE(Rank_Keys!$G:$G,3),Rank_Keys!$G:$G,0)),"") -> Noosa | L36: =IFERROR(INDEX(LGA_Summary!$D:$D,MATCH(LARGE(Rank_Keys!$G:$G,3),Rank_Keys!$G:$G,0)),"") -> 45385 | M36: =IFERROR(INDEX(LGA_Summary!$F:$F,MATCH(LARGE(Rank_Keys!$G:$G,3),Rank_Keys!$G:$G,0)),"") -> 1 | N36: =IFERROR(INDEX(LGA_Summary!$G:$G,MATCH(LARGE(Rank_Keys!$G:$G,3),Rank_Keys!$G:$G,0)),"") -> 1514 | O36: =IFERROR(INDEX(LGA_Summary!$J:$J,MATCH(LARGE(Rank_Keys!$G:$G,3),Rank_Keys!$G:$G,0)),"") -> 0.23051519
A37: 4 | B37: =IFERROR(INDEX(LGA_Summary!$C:$C,MATCH(LARGE(Rank_Keys!$F:$F,4),Rank_Keys!$F:$F,0)),"") -> Ku-ring-gai | C37: =IFERROR(INDEX(LGA_Summary!$D:$D,MATCH(LARGE(Rank_Keys!$F:$F,4),Rank_Keys!$F:$F,0)),"") -> 69492 | D37: =IFERROR(INDEX(LGA_Summary!$F:$F,MATCH(LARGE(Rank_Keys!$F:$F,4),Rank_Keys!$F:$F,0)),"") -> 5 | E37: =IFERROR(INDEX(LGA_Summary!$U:$U,MATCH(LARGE(Rank_Keys!$F:$F,4),Rank_Keys!$F:$F,0)),"") -> 0.20526647 | F37: =IFERROR(INDEX(LGA_Summary!$T:$T,MATCH(LARGE(Rank_Keys!$F:$F,4),Rank_Keys!$F:$F,0)),"") -> 0.40458145 | G37: =IFERROR(INDEX(LGA_Summary!$V:$V,MATCH(LARGE(Rank_Keys!$F:$F,4),Rank_Keys!$F:$F,0)),"") -> 19.931497 | J37: 4 | K37: =IFERROR(INDEX(LGA_Summary!$C:$C,MATCH(LARGE(Rank_Keys!$G:$G,4),Rank_Keys!$G:$G,0)),"") -> Sunshine Coast | L37: =IFERROR(INDEX(LGA_Summary!$D:$D,MATCH(LARGE(Rank_Keys!$G:$G,4),Rank_Keys!$G:$G,0)),"") -> 52638 | M37: =IFERROR(INDEX(LGA_Summary!$F:$F,MATCH(LARGE(Rank_Keys!$G:$G,4),Rank_Keys!$G:$G,0)),"") -> 1 | N37: =IFERROR(INDEX(LGA_Summary!$G:$G,MATCH(LARGE(Rank_Keys!$G:$G,4),Rank_Keys!$G:$G,0)),"") -> 9334 | O37: =IFERROR(INDEX(LGA_Summary!$J:$J,MATCH(LARGE(Rank_Keys!$G:$G,4),Rank_Keys!$G:$G,0)),"") -> 0.22316263
A38: 5 | B38: =IFERROR(INDEX(LGA_Summary!$C:$C,MATCH(LARGE(Rank_Keys!$F:$F,5),Rank_Keys!$F:$F,0)),"") -> Yass Valley | C38: =IFERROR(INDEX(LGA_Summary!$D:$D,MATCH(LARGE(Rank_Keys!$F:$F,5),Rank_Keys!$F:$F,0)),"") -> 67361 | D38: =IFERROR(INDEX(LGA_Summary!$F:$F,MATCH(LARGE(Rank_Keys!$F:$F,5),Rank_Keys!$F:$F,0)),"") -> 4 | E38: =IFERROR(INDEX(LGA_Summary!$U:$U,MATCH(LARGE(Rank_Keys!$F:$F,5),Rank_Keys!$F:$F,0)),"") -> 0.12744716 | F38: =IFERROR(INDEX(LGA_Summary!$T:$T,MATCH(LARGE(Rank_Keys!$F:$F,5),Rank_Keys!$F:$F,0)),"") -> 0.32369097 | G38: =IFERROR(INDEX(LGA_Summary!$V:$V,MATCH(LARGE(Rank_Keys!$F:$F,5),Rank_Keys!$F:$F,0)),"") -> 19.624381 | J38: 5 | K38: =IFERROR(INDEX(LGA_Summary!$C:$C,MATCH(LARGE(Rank_Keys!$G:$G,5),Rank_Keys!$G:$G,0)),"") -> Moreton Bay | L38: =IFERROR(INDEX(LGA_Summary!$D:$D,MATCH(LARGE(Rank_Keys!$G:$G,5),Rank_Keys!$G:$G,0)),"") -> 57332 | M38: =IFERROR(INDEX(LGA_Summary!$F:$F,MATCH(LARGE(Rank_Keys!$G:$G,5),Rank_Keys!$G:$G,0)),"") -> 3 | N38: =IFERROR(INDEX(LGA_Summary!$G:$G,MATCH(LARGE(Rank_Keys!$G:$G,5),Rank_Keys!$G:$G,0)),"") -> 13424 | O38: =IFERROR(INDEX(LGA_Summary!$J:$J,MATCH(LARGE(Rank_Keys!$G:$G,5),Rank_Keys!$G:$G,0)),"") -> 0.22087306
A39: 6 | B39: =IFERROR(INDEX(LGA_Summary!$C:$C,MATCH(LARGE(Rank_Keys!$F:$F,6),Rank_Keys!$F:$F,0)),"") -> Hunters Hill | C39: =IFERROR(INDEX(LGA_Summary!$D:$D,MATCH(LARGE(Rank_Keys!$F:$F,6),Rank_Keys!$F:$F,0)),"") -> 80855 | D39: =IFERROR(INDEX(LGA_Summary!$F:$F,MATCH(LARGE(Rank_Keys!$F:$F,6),Rank_Keys!$F:$F,0)),"") -> 5 | E39: =IFERROR(INDEX(LGA_Summary!$U:$U,MATCH(LARGE(Rank_Keys!$F:$F,6),Rank_Keys!$F:$F,0)),"") -> 0.16379183 | F39: =IFERROR(INDEX(LGA_Summary!$T:$T,MATCH(LARGE(Rank_Keys!$F:$F,6),Rank_Keys!$F:$F,0)),"") -> 0.3504295 | G39: =IFERROR(INDEX(LGA_Summary!$V:$V,MATCH(LARGE(Rank_Keys!$F:$F,6),Rank_Keys!$F:$F,0)),"") -> 18.663767 | J39: 6 | K39: =IFERROR(INDEX(LGA_Summary!$C:$C,MATCH(LARGE(Rank_Keys!$G:$G,6),Rank_Keys!$G:$G,0)),"") -> Redland | L39: =IFERROR(INDEX(LGA_Summary!$D:$D,MATCH(LARGE(Rank_Keys!$G:$G,6),Rank_Keys!$G:$G,0)),"") -> 59533 | M39: =IFERROR(INDEX(LGA_Summary!$F:$F,MATCH(LARGE(Rank_Keys!$G:$G,6),Rank_Keys!$G:$G,0)),"") -> 4 | N39: =IFERROR(INDEX(LGA_Summary!$G:$G,MATCH(LARGE(Rank_Keys!$G:$G,6),Rank_Keys!$G:$G,0)),"") -> 4373 | O39: =IFERROR(INDEX(LGA_Summary!$J:$J,MATCH(LARGE(Rank_Keys!$G:$G,6),Rank_Keys!$G:$G,0)),"") -> 0.21701349
A40: 7 | B40: =IFERROR(INDEX(LGA_Summary!$C:$C,MATCH(LARGE(Rank_Keys!$F:$F,7),Rank_Keys!$F:$F,0)),"") -> Byron | C40: =IFERROR(INDEX(LGA_Summary!$D:$D,MATCH(LARGE(Rank_Keys!$F:$F,7),Rank_Keys!$F:$F,0)),"") -> 39703 | D40: =IFERROR(INDEX(LGA_Summary!$F:$F,MATCH(LARGE(Rank_Keys!$F:$F,7),Rank_Keys!$F:$F,0)),"") -> 1 | E40: =IFERROR(INDEX(LGA_Summary!$U:$U,MATCH(LARGE(Rank_Keys!$F:$F,7),Rank_Keys!$F:$F,0)),"") -> 0.11715178 | F40: =IFERROR(INDEX(LGA_Summary!$T:$T,MATCH(LARGE(Rank_Keys!$F:$F,7),Rank_Keys!$F:$F,0)),"") -> 0.30121442 | G40: =IFERROR(INDEX(LGA_Summary!$V:$V,MATCH(LARGE(Rank_Keys!$F:$F,7),Rank_Keys!$F:$F,0)),"") -> 18.406264 | J40: 7 | K40: =IFERROR(INDEX(LGA_Summary!$C:$C,MATCH(LARGE(Rank_Keys!$G:$G,7),Rank_Keys!$G:$G,0)),"") -> Gold Coast | L40: =IFERROR(INDEX(LGA_Summary!$D:$D,MATCH(LARGE(Rank_Keys!$G:$G,7),Rank_Keys!$G:$G,0)),"") -> 53824 | M40: =IFERROR(INDEX(LGA_Summary!$F:$F,MATCH(LARGE(Rank_Keys!$G:$G,7),Rank_Keys!$G:$G,0)),"") -> 2 | N40: =IFERROR(INDEX(LGA_Summary!$G:$G,MATCH(LARGE(Rank_Keys!$G:$G,7),Rank_Keys!$G:$G,0)),"") -> 17131 | O40: =IFERROR(INDEX(LGA_Summary!$J:$J,MATCH(LARGE(Rank_Keys!$G:$G,7),Rank_Keys!$G:$G,0)),"") -> 0.21574923
A41: 8 | B41: =IFERROR(INDEX(LGA_Summary!$C:$C,MATCH(LARGE(Rank_Keys!$F:$F,8),Rank_Keys!$F:$F,0)),"") -> Eurobodalla | C41: =IFERROR(INDEX(LGA_Summary!$D:$D,MATCH(LARGE(Rank_Keys!$F:$F,8),Rank_Keys!$F:$F,0)),"") -> 43471 | D41: =IFERROR(INDEX(LGA_Summary!$F:$F,MATCH(LARGE(Rank_Keys!$F:$F,8),Rank_Keys!$F:$F,0)),"") -> 1 | E41: =IFERROR(INDEX(LGA_Summary!$U:$U,MATCH(LARGE(Rank_Keys!$F:$F,8),Rank_Keys!$F:$F,0)),"") -> 0.053657664 | F41: =IFERROR(INDEX(LGA_Summary!$T:$T,MATCH(LARGE(Rank_Keys!$F:$F,8),Rank_Keys!$F:$F,0)),"") -> 0.23764579 | G41: =IFERROR(INDEX(LGA_Summary!$V:$V,MATCH(LARGE(Rank_Keys!$F:$F,8),Rank_Keys!$F:$F,0)),"") -> 18.398813 | J41: 8 | K41: =IFERROR(INDEX(LGA_Summary!$C:$C,MATCH(LARGE(Rank_Keys!$G:$G,8),Rank_Keys!$G:$G,0)),"") -> Logan | L41: =IFERROR(INDEX(LGA_Summary!$D:$D,MATCH(LARGE(Rank_Keys!$G:$G,8),Rank_Keys!$G:$G,0)),"") -> 55522 | M41: =IFERROR(INDEX(LGA_Summary!$F:$F,MATCH(LARGE(Rank_Keys!$G:$G,8),Rank_Keys!$G:$G,0)),"") -> 2 | N41: =IFERROR(INDEX(LGA_Summary!$G:$G,MATCH(LARGE(Rank_Keys!$G:$G,8),Rank_Keys!$G:$G,0)),"") -> 8820 | O41: =IFERROR(INDEX(LGA_Summary!$J:$J,MATCH(LARGE(Rank_Keys!$G:$G,8),Rank_Keys!$G:$G,0)),"") -> 0.19795918
A42: 9 | B42: =IFERROR(INDEX(LGA_Summary!$C:$C,MATCH(LARGE(Rank_Keys!$F:$F,9),Rank_Keys!$F:$F,0)),"") -> Ballina | C42: =IFERROR(INDEX(LGA_Summary!$D:$D,MATCH(LARGE(Rank_Keys!$F:$F,9),Rank_Keys!$F:$F,0)),"") -> 49458 | D42: =IFERROR(INDEX(LGA_Summary!$F:$F,MATCH(LARGE(Rank_Keys!$F:$F,9),Rank_Keys!$F:$F,0)),"") -> 1 | E42: =IFERROR(INDEX(LGA_Summary!$U:$U,MATCH(LARGE(Rank_Keys!$F:$F,9),Rank_Keys!$F:$F,0)),"") -> 0.076207465 | F42: =IFERROR(INDEX(LGA_Summary!$T:$T,MATCH(LARGE(Rank_Keys!$F:$F,9),Rank_Keys!$F:$F,0)),"") -> 0.25911474 | G42: =IFERROR(INDEX(LGA_Summary!$V:$V,MATCH(LARGE(Rank_Keys!$F:$F,9),Rank_Keys!$F:$F,0)),"") -> 18.290728 | J42: 9 | K42: =IFERROR(INDEX(LGA_Summary!$C:$C,MATCH(LARGE(Rank_Keys!$G:$G,9),Rank_Keys!$G:$G,0)),"") -> Scenic Rim | L42: =IFERROR(INDEX(LGA_Summary!$D:$D,MATCH(LARGE(Rank_Keys!$G:$G,9),Rank_Keys!$G:$G,0)),"") -> 48993 | M42: =IFERROR(INDEX(LGA_Summary!$F:$F,MATCH(LARGE(Rank_Keys!$G:$G,9),Rank_Keys!$G:$G,0)),"") -> 1 | N42: =IFERROR(INDEX(LGA_Summary!$G:$G,MATCH(LARGE(Rank_Keys!$G:$G,9),Rank_Keys!$G:$G,0)),"") -> 1011 | O42: =IFERROR(INDEX(LGA_Summary!$J:$J,MATCH(LARGE(Rank_Keys!$G:$G,9),Rank_Keys!$G:$G,0)),"") -> 0.18199802
A43: 10 | B43: =IFERROR(INDEX(LGA_Summary!$C:$C,MATCH(LARGE(Rank_Keys!$F:$F,10),Rank_Keys!$F:$F,0)),"") -> Queanbeyan-Palerang Regional | C43: =IFERROR(INDEX(LGA_Summary!$D:$D,MATCH(LARGE(Rank_Keys!$F:$F,10),Rank_Keys!$F:$F,0)),"") -> 74963 | D43: =IFERROR(INDEX(LGA_Summary!$F:$F,MATCH(LARGE(Rank_Keys!$F:$F,10),Rank_Keys!$F:$F,0)),"") -> 5 | E43: =IFERROR(INDEX(LGA_Summary!$U:$U,MATCH(LARGE(Rank_Keys!$F:$F,10),Rank_Keys!$F:$F,0)),"") -> 0.14453922 | F43: =IFERROR(INDEX(LGA_Summary!$T:$T,MATCH(LARGE(Rank_Keys!$F:$F,10),Rank_Keys!$F:$F,0)),"") -> 0.32554792 | G43: =IFERROR(INDEX(LGA_Summary!$V:$V,MATCH(LARGE(Rank_Keys!$F:$F,10),Rank_Keys!$F:$F,0)),"") -> 18.100871 | J43: 10 | K43: =IFERROR(INDEX(LGA_Summary!$C:$C,MATCH(LARGE(Rank_Keys!$G:$G,10),Rank_Keys!$G:$G,0)),"") -> Cairns | L43: =IFERROR(INDEX(LGA_Summary!$D:$D,MATCH(LARGE(Rank_Keys!$G:$G,10),Rank_Keys!$G:$G,0)),"") -> 55547 | M43: =IFERROR(INDEX(LGA_Summary!$F:$F,MATCH(LARGE(Rank_Keys!$G:$G,10),Rank_Keys!$G:$G,0)),"") -> 3 | N43: =IFERROR(INDEX(LGA_Summary!$G:$G,MATCH(LARGE(Rank_Keys!$G:$G,10),Rank_Keys!$G:$G,0)),"") -> 3556 | O43: =IFERROR(INDEX(LGA_Summary!$J:$J,MATCH(LARGE(Rank_Keys!$G:$G,10),Rank_Keys!$G:$G,0)),"") -> 0.1704162
A46: QLD LGAs — most new BEVs registered (recent window, count) | J46: VIC suburbs (postcodes) — most BEVs per 1,000 vehicles
A47: # | B47: LGA | C47: Median income ($) | D47: Income group | E47: New regos | F47: New BEVs | J47: # | K47: Postcode | L47: Suburbs | M47: Median taxable income ($) | N47: Income group | O47: BEVs | P47: Per 1,000
...

Sheet Fuel_Crisis
A1: The 2026 fuel crisis — did the price shock change who buys BEVs?
A2: Crisis = months from the detected onset (Inputs) to the latest month, compared with the same calendar months a year earlier (controls for seasonality such as the June EOFY peak).
A4: Month | B4: NSW retail ULP (c/L) | C4: NSW retail diesel (c/L) | D4: QLD retail ULP (c/L) | E4: QLD retail diesel (c/L) | F4: Terminal gate petrol (c/L) | G4: Crisis month? (1 = yes) | H4: NSW BEV share — all areas | I4: QLD BEV share — all areas
A5: =Flow_Group_Month!A5 -> 44927 | B5: =IFERROR(INDEX(Fuel_Prices!$B:$B,MATCH($A5,Fuel_Prices!$A:$A,0)),"") -> 179.26 | C5: =IFERROR(INDEX(Fuel_Prices!$C:$C,MATCH($A5,Fuel_Prices!$A:$A,0)),"") -> 209.91 | D5: =IFERROR(INDEX(Fuel_Prices!$D:$D,MATCH($A5,Fuel_Prices!$A:$A,0)),"") -> 179.69 | E5: =IFERROR(INDEX(Fuel_Prices!$E:$E,MATCH($A5,Fuel_Prices!$A:$A,0)),"") -> 210.17 | F5: =IFERROR(INDEX(Fuel_Prices!$F:$F,MATCH($A5,Fuel_Prices!$A:$A,0)),"") -> 167.95 | G5: =IF(AND(A5>=Inputs!$B$28,A5<=Inputs!$B$29),1,0) -> 0 | H5: =Flow_Group_Month!AA5 -> 0.07891196 | I5: =Flow_Group_Month!AG5 -> 0.11648822
A6: =Flow_Group_Month!A6 -> 44958 | B6: =IFERROR(INDEX(Fuel_Prices!$B:$B,MATCH($A6,Fuel_Prices!$A:$A,0)),"") -> 184.98 | C6: =IFERROR(INDEX(Fuel_Prices!$C:$C,MATCH($A6,Fuel_Prices!$A:$A,0)),"") -> 204.56 | D6: =IFERROR(INDEX(Fuel_Prices!$D:$D,MATCH($A6,Fuel_Prices!$A:$A,0)),"") -> 182.96 | E6: =IFERROR(INDEX(Fuel_Prices!$E:$E,MATCH($A6,Fuel_Prices!$A:$A,0)),"") -> 202.99 | F6: =IFERROR(INDEX(Fuel_Prices!$F:$F,MATCH($A6,Fuel_Prices!$A:$A,0)),"") -> 171.66 | G6: =IF(AND(A6>=Inputs!$B$28,A6<=Inputs!$B$29),1,0) -> 0 | H6: =Flow_Group_Month!AA6 -> 0.09663282 | I6: =Flow_Group_Month!AG6 -> 0.091915704
A7: =Flow_Group_Month!A7 -> 44986 | B7: =IFERROR(INDEX(Fuel_Prices!$B:$B,MATCH($A7,Fuel_Prices!$A:$A,0)),"") -> 184.5 | C7: =IFERROR(INDEX(Fuel_Prices!$C:$C,MATCH($A7,Fuel_Prices!$A:$A,0)),"") -> 200.31 | D7: =IFERROR(INDEX(Fuel_Prices!$D:$D,MATCH($A7,Fuel_Prices!$A:$A,0)),"") -> 183.62 | E7: =IFERROR(INDEX(Fuel_Prices!$E:$E,MATCH($A7,Fuel_Prices!$A:$A,0)),"") -> 198.56 | F7: =IFERROR(INDEX(Fuel_Prices!$F:$F,MATCH($A7,Fuel_Prices!$A:$A,0)),"") -> 172.9 | G7: =IF(AND(A7>=Inputs!$B$28,A7<=Inputs!$B$29),1,0) -> 0 | H7: =Flow_Group_Month!AA7 -> 0.11175976 | I7: =Flow_Group_Month!AG7 -> 0.087064915
A8: =Flow_Group_Month!A8 -> 45017 | B8: =IFERROR(INDEX(Fuel_Prices!$B:$B,MATCH($A8,Fuel_Prices!$A:$A,0)),"") -> 189.69 | C8: =IFERROR(INDEX(Fuel_Prices!$C:$C,MATCH($A8,Fuel_Prices!$A:$A,0)),"") -> 197.21 | D8: =IFERROR(INDEX(Fuel_Prices!$D:$D,MATCH($A8,Fuel_Prices!$A:$A,0)),"") -> 190.31 | E8: =IFERROR(INDEX(Fuel_Prices!$E:$E,MATCH($A8,Fuel_Prices!$A:$A,0)),"") -> 195.9 | F8: =IFERROR(INDEX(Fuel_Prices!$F:$F,MATCH($A8,Fuel_Prices!$A:$A,0)),"") -> 177.26 | G8: =IF(AND(A8>=Inputs!$B$28,A8<=Inputs!$B$29),1,0) -> 0 | H8: =Flow_Group_Month!AA8 -> 0.062225956 | I8: =Flow_Group_Month!AG8 -> 0.11344727
A9: =Flow_Group_Month!A9 -> 45047 | B9: =IFERROR(INDEX(Fuel_Prices!$B:$B,MATCH($A9,Fuel_Prices!$A:$A,0)),"") -> 181.63 | C9: =IFERROR(INDEX(Fuel_Prices!$C:$C,MATCH($A9,Fuel_Prices!$A:$A,0)),"") -> 190.15 | D9: =IFERROR(INDEX(Fuel_Prices!$D:$D,MATCH($A9,Fuel_Prices!$A:$A,0)),"") -> 180.93 | E9: =IFERROR(INDEX(Fuel_Prices!$E:$E,MATCH($A9,Fuel_Prices!$A:$A,0)),"") -> 188.96 | F9: =IFERROR(INDEX(Fuel_Prices!$F:$F,MATCH($A9,Fuel_Prices!$A:$A,0)),"") -> 166.46 | G9: =IF(AND(A9>=Inputs!$B$28,A9<=Inputs!$B$29),1,0) -> 0 | H9: =Flow_Group_Month!AA9 -> 0.086556492 | I9: =Flow_Group_Month!AG9 -> 0.080929408
A10: =Flow_Group_Month!A10 -> 45078 | B10: =IFERROR(INDEX(Fuel_Prices!$B:$B,MATCH($A10,Fuel_Prices!$A:$A,0)),"") -> 183.99 | C10: =IFERROR(INDEX(Fuel_Prices!$C:$C,MATCH($A10,Fuel_Prices!$A:$A,0)),"") -> 185.55 | D10: =IFERROR(INDEX(Fuel_Prices!$D:$D,MATCH($A10,Fuel_Prices!$A:$A,0)),"") -> 183.43 | E10: =IFERROR(INDEX(Fuel_Prices!$E:$E,MATCH($A10,Fuel_Prices!$A:$A,0)),"") -> 183.82 | F10: =IFERROR(INDEX(Fuel_Prices!$F:$F,MATCH($A10,Fuel_Prices!$A:$A,0)),"") -> 167.33 | G10: =IF(AND(A10>=Inputs!$B$28,A10<=Inputs!$B$29),1,0) -> 0 | H10: =Flow_Group_Month!AA10 -> 0.077192216 | I10: =Flow_Group_Month!AG10 -> 0.11262366
A11: =Flow_Group_Month!A11 -> 45108 | B11: =IFERROR(INDEX(Fuel_Prices!$B:$B,MATCH($A11,Fuel_Prices!$A:$A,0)),"") -> 184.66 | C11: =IFERROR(INDEX(Fuel_Prices!$C:$C,MATCH($A11,Fuel_Prices!$A:$A,0)),"") -> 185.54 | D11: =IFERROR(INDEX(Fuel_Prices!$D:$D,MATCH($A11,Fuel_Prices!$A:$A,0)),"") -> 182.62 | E11: =IFERROR(INDEX(Fuel_Prices!$E:$E,MATCH($A11,Fuel_Prices!$A:$A,0)),"") -> 183.34 | F11: =IFERROR(INDEX(Fuel_Prices!$F:$F,MATCH($A11,Fuel_Prices!$A:$A,0)),"") -> 169.17 | G11: =IF(AND(A11>=Inputs!$B$28,A11<=Inputs!$B$29),1,0) -> 0 | H11: =Flow_Group_Month!AA11 -> 0.080654245 | I11: =Flow_Group_Month!AG11 -> 0.077892885
A12: =Flow_Group_Month!A12 -> 45139 | B12: =IFERROR(INDEX(Fuel_Prices!$B:$B,MATCH($A12,Fuel_Prices!$A:$A,0)),"") -> 198.73 | C12: =IFERROR(INDEX(Fuel_Prices!$C:$C,MATCH($A12,Fuel_Prices!$A:$A,0)),"") -> 207.13 | D12: =IFERROR(INDEX(Fuel_Prices!$D:$D,MATCH($A12,Fuel_Prices!$A:$A,0)),"") -> 199.16 | E12: =IFERROR(INDEX(Fuel_Prices!$E:$E,MATCH($A12,Fuel_Prices!$A:$A,0)),"") -> 209.09 | F12: =IFERROR(INDEX(Fuel_Prices!$F:$F,MATCH($A12,Fuel_Prices!$A:$A,0)),"") -> 185.75 | G12: =IF(AND(A12>=Inputs!$B$28,A12<=Inputs!$B$29),1,0) -> 0 | H12: =Flow_Group_Month!AA12 -> 0.064193628 | I12: =Flow_Group_Month!AG12 -> 0.14211618
A13: =Flow_Group_Month!A13 -> 45170 | B13: =IFERROR(INDEX(Fuel_Prices!$B:$B,MATCH($A13,Fuel_Prices!$A:$A,0)),"") -> 207.28 | C13: =IFERROR(INDEX(Fuel_Prices!$C:$C,MATCH($A13,Fuel_Prices!$A:$A,0)),"") -> 218.69 | D13: =IFERROR(INDEX(Fuel_Prices!$D:$D,MATCH($A13,Fuel_Prices!$A:$A,0)),"") -> 205.61 | E13: =IFERROR(INDEX(Fuel_Prices!$E:$E,MATCH($A13,Fuel_Prices!$A:$A,0)),"") -> 219.72 | F13: =IFERROR(INDEX(Fuel_Prices!$F:$F,MATCH($A13,Fuel_Prices!$A:$A,0)),"") -> 192.49 | G13: =IF(AND(A13>=Inputs!$B$28,A13<=Inputs!$B$29),1,0) -> 0 | H13: =Flow_Group_Month!AA13 -> 0.092629466 | I13: =Flow_Group_Month!AG13 -> 0.11346644
A14: =Flow_Group_Month!A14 -> 45200 | B14: =IFERROR(INDEX(Fuel_Prices!$B:$B,MATCH($A14,Fuel_Prices!$A:$A,0)),"") -> 203.45 | C14: =IFERROR(INDEX(Fuel_Prices!$C:$C,MATCH($A14,Fuel_Prices!$A:$A,0)),"") -> 222.52 | D14: =IFERROR(INDEX(Fuel_Prices!$D:$D,MATCH($A14,Fuel_Prices!$A:$A,0)),"") -> 206.54 | E14: =IFERROR(INDEX(Fuel_Prices!$E:$E,MATCH($A14,Fuel_Prices!$A:$A,0)),"") -> 222.61 | F14: =IFERROR(INDEX(Fuel_Prices!$F:$F,MATCH($A14,Fuel_Prices!$A:$A,0)),"") -> 182.07 | G14: =IF(AND(A14>=Inputs!$B$28,A14<=Inputs!$B$29),1,0) -> 0 | H14: =Flow_Group_Month!AA14 -> 0.065857544 | I14: =Flow_Group_Month!AG14 -> 0.079669297
A15: =Flow_Group_Month!A15 -> 45231 | B15: =IFERROR(INDEX(Fuel_Prices!$B:$B,MATCH($A15,Fuel_Prices!$A:$A,0)),"") -> 200.08 | C15: =IFERROR(INDEX(Fuel_Prices!$C:$C,MATCH($A15,Fuel_Prices!$A:$A,0)),"") -> 214.2 | D15: =IFERROR(INDEX(Fuel_Prices!$D:$D,MATCH($A15,Fuel_Prices!$A:$A,0)),"") -> 196.65 | E15: =IFERROR(INDEX(Fuel_Prices!$E:$E,MATCH($A15,Fuel_Prices!$A:$A,0)),"") -> 213.67 | F15: =IFERROR(INDEX(Fuel_Prices!$F:$F,MATCH($A15,Fuel_Prices!$A:$A,0)),"") -> 177.5 | G15: =IF(AND(A15>=Inputs!$B$28,A15<=Inputs!$B$29),1,0) -> 0 | H15: =Flow_Group_Month!AA15 -> 0.092011711 | I15: =Flow_Group_Month!AG15 -> 0.14188138
A16: =Flow_Group_Month!A16 -> 45261 | B16: =IFERROR(INDEX(Fuel_Prices!$B:$B,MATCH($A16,Fuel_Prices!$A:$A,0)),"") -> 190.94 | C16: =IFERROR(INDEX(Fuel_Prices!$C:$C,MATCH($A16,Fuel_Prices!$A:$A,0)),"") -> 201.16 | D16: =IFERROR(INDEX(Fuel_Prices!$D:$D,MATCH($A16,Fuel_Prices!$A:$A,0)),"") -> 185.85 | E16: =IFERROR(INDEX(Fuel_Prices!$E:$E,MATCH($A16,Fuel_Prices!$A:$A,0)),"") -> 199.18 | F16: =IFERROR(INDEX(Fuel_Prices!$F:$F,MATCH($A16,Fuel_Prices!$A:$A,0)),"") -> 167.88 | G16: =IF(AND(A16>=Inputs!$B$28,A16<=Inputs!$B$29),1,0) -> 0 | H16: =Flow_Group_Month!AA16 -> 0.082733888 | I16: =Flow_Group_Month!AG16 -> 0.10852218
... A48: =Flow_Group_Month!A48 -> 46235 | B48: =IFERROR(INDEX(Fuel_Prices!$B:$B,MATCH($A48,Fuel_Prices!$A:$A,0)),"") -> 203.92 | C48: =IFERROR(INDEX(Fuel_Prices!$C:$C,MATCH($A48,Fuel_Prices!$A:$A,0)),"") -> 248.38 | D48: =IFERROR(INDEX(Fuel_Prices!$D:$D,MATCH($A48,Fuel_Prices!$A:$A,0)),"") -> 206.48 | E48: =IFERROR(INDEX(Fuel_Prices!$E:$E,MATCH($A48,Fuel_Prices!$A:$A,0)),"") -> 250.47 | F48: =IFERROR(INDEX(Fuel_Prices!$F:$F,MATCH($A48,Fuel_Prices!$A:$A,0)),"") -> 195.92 | G48: =IF(AND(A48>=Inputs!$B$28,A48<=Inputs!$B$29),1,0) -> 1 | H48: =Flow_Group_Month!AA48 -> 0.25882262 | I48: =Flow_Group_Month!AG48 -> 0.32715469
A51: New private registrations by income group — crisis months vs same months a year earlier vs pre-crisis months
A52: State | B52: Income group | C52: New regos (crisis) | D52: BEV (crisis) | E52: BEV share (crisis) | F52: New regos (year earlier) | G52: BEV (year earlier) | H52: BEV share (year earlier) | I52: Change vs year earlier (pp) | J52: BEV share multiple (× year earlier) | K52: Extra BEVs vs year earlier | L52: Share of the extra BEVs | M52: Share of crisis new regos | N52: Non-BEV new regos, change vs year earlier
